Workbook

Sheet Consumo salmoura
B1: AZEITONA VERDE | O1: CHAMPIGNON | V1: AZEITONA PRETA
B2: LINHA DE PRODUTOS - DOYPACK 80g/ 120g/150g/1,01Kg | O2: LINHA DE PRODUTOS - DOYPACK 100/1,01Kg | W2: LINHA DE PRODUTOS - POTES DE VIDRO 400g
B3: INGREDIENTE | C3: % | D3: 0.08 | E3: CUSTO | F3: 0.12 | G3: CUSTO | H3: 0.15 | I3: CUSTO | J3: 1.01 | K3: CUSTO | L3: 0.05 | O3: INGREDIENTE | P3: % | Q3: 0.1 | R3: CUSTO | S3: 1.01 | T3: CUSTO | V3: INGREDIENTE | W3: % | X3: 0.4 | Y3: CUSTO | Z3: 0.2 | AA3: CUSTO
B4: Água potável | C4: 0.9544 | D4: =C4*$D$10 -> 0.085896 | F4: =C4*$F$10 -> 0.14316 | H4: =C4*$H$10 -> 0.114528 | J4: =C4*$J$10 -> 0.563096 | O4: Água potável | P4: 0.9404 | Q4: =P4*$Q$11 -> 0.065828 | S4: =$S$11*P4 -> 0.554836 | V4: Água potável | W4: 0.9367 | X4: =W4*$X$10 -> 0.393414
A5: 9794 | B5: Sal | C5: 0.0427 | D5: =C5*$D$10 -> 0.003843 | E5: =VLOOKUP($A5,INSUMOS!$B:$D,3,0)*D5 -> 0.0826245 | F5: =C5*$F$10 -> 0.006405 | G5: =VLOOKUP($A5,INSUMOS!$B:$D,3,0)*F5 -> 0.1377075 | H5: =C5*$H$10 -> 0.005124 | I5: =VLOOKUP($A5,INSUMOS!$B:$D,3,0)*H5 -> 0.110166 | J5: =C5*$J$10 -> 0.025193 | K5: =VLOOKUP($A5,INSUMOS!$B:$D,3,0)*J5 -> 0.5416495 | L5: =C5*$L$10 -> 0.005124 | M5: =VLOOKUP($A5,INSUMOS!$B:$D,3,0)*L5 -> 0.110166 | N5: 9794 | O5: Sal | P5: 0.054 | Q5: =P5*$Q$11 -> 0.00378 | R5: =VLOOKUP($N5,INSUMOS!$B:$D,3,0)*Q5 -> 0.08127 | S5: =$S$11*P5 -> 0.03186 | T5: =VLOOKUP($N5,INSUMOS!$B:$D,3,0)*S5 -> 0.68499 | U5: 9794 | V5: Sal | W5: 0.06 | X5: =W5*$X$10 -> 0.0252 | Y5: =VLOOKUP($U5,INSUMOS!$B:$D,3,0)*X5 -> 0.5418 | Z5: =W5*$Z$10 -> 0.0111 | AA5: =VLOOKUP($U5,INSUMOS!$B:$D,3,0)*Z5 -> 0.23865
A6: 9789 | B6: Ácido Cítrico | C6: 0.0016 | D6: =C6*$D$10 -> 0.000144 | E6: =VLOOKUP($A6,INSUMOS!$B:$D,3,0)*D6 -> 0.0017856 | F6: =C6*$F$10 -> 0.00024 | G6: =VLOOKUP($A6,INSUMOS!$B:$D,3,0)*F6 -> 0.002976 | H6: =C6*$H$10 -> 0.000192 | I6: =VLOOKUP($A6,INSUMOS!$B:$D,3,0)*H6 -> 0.0023808 | J6: =C6*$J$10 -> 0.000944 | K6: =VLOOKUP($A6,INSUMOS!$B:$D,3,0)*J6 -> 0.0117056 | L6: =C6*$L$10 -> 0.000192 | M6: =VLOOKUP($A6,INSUMOS!$B:$D,3,0)*L6 -> 0.0023808 | N6: 9789 | O6: Ácido Cítrico | P6: 0.002 | Q6: =P6*$Q$11 -> 0.00014 | R6: =VLOOKUP($N6,INSUMOS!$B:$D,3,0)*Q6 -> 0.001736 | S6: =$S$11*P6 -> 0.00118 | T6: =VLOOKUP($N6,INSUMOS!$B:$D,3,0)*S6 -> 0.014632 | U6: 9789 | V6: Ácido Cítrico | W6: 0.002 | X6: =W6*$X$10 -> 0.00084 | Y6: =VLOOKUP($U6,INSUMOS!$B:$D,3,0)*X6 -> 0.010416 | Z6: =W6*$Z$10 -> 0.00037 | AA6: =VLOOKUP($U6,INSUMOS!$B:$D,3,0)*Z6 -> 0.004588
A7: 9511 | B7: Acido Lactico | C7: 0.0005 | D7: =C7*$D$10 -> 4.5e-05 | E7: =VLOOKUP($A7,INSUMOS!$B:$D,3,0)*D7 -> 0.000684 | F7: =C7*$F$10 -> 7.5e-05 | G7: =VLOOKUP($A7,INSUMOS!$B:$D,3,0)*F7 -> 0.00114 | H7: =C7*$H$10 -> 6e-05 | I7: =VLOOKUP($A7,INSUMOS!$B:$D,3,0)*H7 -> 0.000912 | J7: =C7*$J$10 -> 0.000295 | K7: =VLOOKUP($A7,INSUMOS!$B:$D,3,0)*J7 -> 0.004484 | L7: =C7*$L$10 -> 6e-05 | M7: =VLOOKUP($A7,INSUMOS!$B:$D,3,0)*L7 -> 0.000912 | N7: 9511 | O7: Acido Lactico | P7: 0.0015 | Q7: =P7*$Q$11 -> 0.000105 | R7: =VLOOKUP($N7,INSUMOS!$B:$D,3,0)*Q7 -> 0.001596 | S7: =$S$11*P7 -> 0.000885 | T7: =VLOOKUP($N7,INSUMOS!$B:$D,3,0)*S7 -> 0.013452 | U7: 9792 | V7: Benzoato de Sódio | W7: 0.0005 | X7: =W7*$X$10 -> 0.00021 | Y7: =VLOOKUP($U7,INSUMOS!$B:$D,3,0)*X7 -> 0.005964 | Z7: =W7*$Z$10 -> 9.25e-05 | AA7: =VLOOKUP($U7,INSUMOS!$B:$D,3,0)*Z7 -> 0.002627
A8: 9792 | B8: Benzoato de Sódio | C8: 0.0003 | D8: =C8*$D$10 -> 2.7e-05 | E8: =VLOOKUP($A8,INSUMOS!$B:$D,3,0)*D8 -> 0.0007668 | F8: =C8*$F$10 -> 4.5e-05 | G8: =VLOOKUP($A8,INSUMOS!$B:$D,3,0)*F8 -> 0.001278 | H8: =C8*$H$10 -> 3.6e-05 | I8: =VLOOKUP($A8,INSUMOS!$B:$D,3,0)*H8 -> 0.0010224 | J8: =C8*$J$10 -> 0.000177 | K8: =VLOOKUP($A8,INSUMOS!$B:$D,3,0)*J8 -> 0.0050268 | L8: =C8*$L$10 -> 3.6e-05 | M8: =VLOOKUP($A8,INSUMOS!$B:$D,3,0)*L8 -> 0.0010224 | N8: 9792 | O8: Benzoato de Sódio | P8: 0.001 | Q8: =P8*$Q$11 -> 7e-05 | R8: =VLOOKUP($N8,INSUMOS!$B:$D,3,0)*Q8 -> 0.001988 | S8: =$S$11*P8 -> 0.00059 | T8: =VLOOKUP($N8,INSUMOS!$B:$D,3,0)*S8 -> 0.016756 | U8: 9790 | V8: Sorbato de Potássio | W8: 0.0005 | X8: =W8*$X$10 -> 0.00021 | Y8: =VLOOKUP($U8,INSUMOS!$B:$D,3,0)*X8 -> 0.005397 | Z8: =W8*$Z$10 -> 9.25e-05 | AA8: =VLOOKUP($U8,INSUMOS!$B:$D,3,0)*Z8 -> 0.00237725
A9: 9790 | B9: Sorbato de Potássio | C9: 0.0005 | D9: =C9*$D$10 -> 4.5e-05 | E9: =VLOOKUP($A9,INSUMOS!$B:$D,3,0)*D9 -> 0.0011565 | F9: =C9*$F$10 -> 7.5e-05 | G9: =VLOOKUP($A9,INSUMOS!$B:$D,3,0)*F9 -> 0.0019275 | H9: =C9*$H$10 -> 6e-05 | I9: =VLOOKUP($A9,INSUMOS!$B:$D,3,0)*H9 -> 0.001542 | J9: =C9*$J$10 -> 0.000295 | K9: =VLOOKUP($A9,INSUMOS!$B:$D,3,0)*J9 -> 0.0075815 | L9: =C9*$L$10 -> 6e-05 | M9: =VLOOKUP($A9,INSUMOS!$B:$D,3,0)*L9 -> 0.001542 | N9: 9790 | O9: Sorbato de Potássio | P9: 0.001 | Q9: =P9*$Q$11 -> 7e-05 | R9: =VLOOKUP($N9,INSUMOS!$B:$D,3,0)*Q9 -> 0.001799 | S9: =$S$11*P9 -> 0.00059 | T9: =VLOOKUP($N9,INSUMOS!$B:$D,3,0)*S9 -> 0.015163 | U9: 11342 | V9: Cloreto de Calcio | W9: 0.0003 | X9: =W9*$X$10 -> 0.000126 | Y9: =VLOOKUP($U9,INSUMOS!$B:$D,3,0)*X9 -> 0.001575 | Z9: =W9*$Z$10 -> 5.55e-05 | AA9: =VLOOKUP($U9,INSUMOS!$B:$D,3,0)*Z9 -> 0.00069375
B10: Salmoura total | C10: 1 | D10: 0.09 | E10: =SUM(E5:E9) -> 0.0870174 | F10: 0.15 | G10: =SUM(G5:G9) -> 0.145029 | H10: 0.12 | I10: =SUM(I5:I9) -> 0.1160232 | J10: 0.59 | K10: =SUM(K5:K9) -> 0.5704474 | L10: 0.12 | M10: =SUM(M5:M9) -> 0.1160232 | N10: 10718 | O10: Metabissulfito de Sódio | P10: 5e-05 | Q10: =P10*$Q$11 -> 3.5e-06 | R10: =VLOOKUP($N10,INSUMOS!$B:$D,3,0)*Q10 -> 3.115e-05 | S10: =$S$11*P10 -> 2.95e-05 | T10: =VLOOKUP($N10,INSUMOS!$B:$D,3,0)*S10 -> 0.00026255 | V10: Salmoura total | W10: 1 | X10: 0.42 | Y10: =SUM(Y5:Y9) -> 0.565152 | Z10: 0.185 | AA10: =SUM(AA5:AA9) -> 0.248936
O11: Salmoura total | P11: 1 | Q11: 0.07 | R11: =SUM(R5:R10) -> 0.08842015 | S11: 0.59 | T11: =SUM(T5:T10) -> 0.74525555
B12: LINHA DE PRODUTOS - POTES DE VIDRO 160g/500g
B13: INGREDIENTE | C13: % | D13: 0.16 | E13: CUSTO | F13: 0.2 | G13: CUSTO | H13: 0.5 | I13: CUSTO | J13: 0.45 | K13: CUSTO | L13: 0.4 | M13: CUSTO | O13: LINHA DE PRODUTOS - POTES DE VIDRO 200g | V13: LINHA DE PRODUTOS - BALDES 2kg
B14: Água potável | C14: 0.9539 | D14: =C14*$F$18 -> 0.1764715 | F14: 0.305248 | H14: 0.305248 | J14: 0.305248 | L14: 0.305248 | O14: INGREDIENTE | P14: % | Q14: 0.2 | R14: CUSTO | S14: 0.16 | T14: CUSTO | V14: INGREDIENTE | W14: % | X14: 2 | Y14: CUSTO
A15: 9794 | B15: Sal | C15: 0.044 | D15: =C15*$D$18 -> 0.00814 | E15: =VLOOKUP($A15,INSUMOS!$B:$D,3,0)*D15 -> 0.17501 | F15: 0.00814 | G15: =VLOOKUP($A15,INSUMOS!$B:$D,3,0)*F15 -> 0.17501 | H15: 0.01408 | I15: =VLOOKUP($A15,INSUMOS!$B:$D,3,0)*H15 -> 0.30272 | J15: 0.01408 | K15: =VLOOKUP($A15,INSUMOS!$B:$D,3,0)*J15 -> 0.30272 | L15: 0.01408 | M15: =VLOOKUP($A15,INSUMOS!$B:$D,3,0)*L15 -> 0.30272 | O15: Água potável | P15: 0.9404 | Q15: =P15*$Q$22 -> 0.136358 | S15: 0.136358 | V15: Água potável | W15: 0.9367 | X15: =W15*$X$21 -> 0.9367
A16: 9789 | B16: Ácido Cítrico | C16: 0.0016 | D16: =C16*$D$18 -> 0.000296 | E16: =VLOOKUP($A16,INSUMOS!$B:$D,3,0)*D16 -> 0.0036704 | F16: 0.000296 | G16: =VLOOKUP($A16,INSUMOS!$B:$D,3,0)*F16 -> 0.0036704 | H16: 0.000512 | I16: =VLOOKUP($A16,INSUMOS!$B:$D,3,0)*H16 -> 0.0063488 | J16: 0.000512 | K16: =VLOOKUP($A16,INSUMOS!$B:$D,3,0)*J16 -> 0.0063488 | L16: 0.000512 | M16: =VLOOKUP($A16,INSUMOS!$B:$D,3,0)*L16 -> 0.0063488 | N16: 9794 | O16: Sal | P16: 0.054 | Q16: =P16*$Q$22 -> 0.00783 | R16: =VLOOKUP($N16,INSUMOS!$B:$D,3,0)*Q16 -> 0.168345 | S16: 0.00783 | T16: =VLOOKUP($N16,INSUMOS!$B:$D,3,0)*S16 -> 0.168345 | U16: 9794 | V16: Sal | W16: 0.06 | X16: =W16*$X$21 -> 0.06 | Y16: =VLOOKUP($U16,INSUMOS!$B:$D,3,0)*X16 -> 1.29
A17: 9791 | B17: Acido Ascorbico | C17: 0.0005 | D17: =C17*$D$18 -> 9.25e-05 | E17: =VLOOKUP($A17,INSUMOS!$B:$D,3,0)*D17 -> 0.0019425 | F17: 9.25e-05 | G17: =VLOOKUP($A17,INSUMOS!$B:$D,3,0)*F17 -> 0.0019425 | H17: 0.00016 | I17: =VLOOKUP($A17,INSUMOS!$B:$D,3,0)*H17 -> 0.00336 | J17: 0.00016 | K17: =VLOOKUP($A17,INSUMOS!$B:$D,3,0)*J17 -> 0.00336 | L17: 0.00016 | M17: =VLOOKUP($A17,INSUMOS!$B:$D,3,0)*L17 -> 0.00336 | N17: 9789 | O17: Ácido Cítrico | P17: 0.002 | Q17: =P17*$Q$22 -> 0.00029 | R17: =VLOOKUP($N17,INSUMOS!$B:$D,3,0)*Q17 -> 0.003596 | S17: 0.00029 | T17: =VLOOKUP($N17,INSUMOS!$B:$D,3,0)*S17 -> 0.003596 | U17: 9789 | V17: Ácido Cítrico | W17: 0.002 | X17: =W17*$X$21 -> 0.002 | Y17: =VLOOKUP($U17,INSUMOS!$B:$D,3,0)*X17 -> 0.0248
B18: Salmoura total | C18: 1 | D18: 0.185 | E18: =SUM(E13:E17) -> 0.1806229 | F18: 0.185 | G18: =SUM(G13:G17) -> 0.1806229 | H18: 0.32 | I18: =SUM(I13:I17) -> 0.3124288 | J18: 0.32 | K18: =SUM(K13:K17) -> 0.3124288 | L18: 0.32 | M18: =SUM(M13:M17) -> 0.3124288 | N18: 9511 | O18: Acido Lactico | P18: 0.0015 | Q18: =P18*$Q$22 -> 0.0002175 | R18: =VLOOKUP($N18,INSUMOS!$B:$D,3,0)*Q18 -> 0.003306 | S18: 0.0002175 | T18: =VLOOKUP($N18,INSUMOS!$B:$D,3,0)*S18 -> 0.003306 | U18: 9792 | V18: Benzoato de Sódio | W18: 0.0005 | X18: =W18*$X$21 -> 0.0005 | Y18: =VLOOKUP($U18,INSUMOS!$B:$D,3,0)*X18 -> 0.0142
N19: 9792 | O19: Benzoato de Sódio | P19: 0.001 | Q19: =P19*$Q$22 -> 0.000145 | R19: =VLOOKUP($N19,INSUMOS!$B:$D,3,0)*Q19 -> 0.004118 | S19: 0.000145 | T19: =VLOOKUP($N19,INSUMOS!$B:$D,3,0)*S19 -> 0.004118 | U19: 9790 | V19: Sorbato de Potássio | W19: 0.0005 | X19: =W19*$X$21 -> 0.0005 | Y19: =VLOOKUP($U19,INSUMOS!$B:$D,3,0)*X19 -> 0.01285
B20: LINHA DE PRODUTOS - BALDES 2KG | N20: 9790 | O20: Sorbato de Potássio | P20: 0.001 | Q20: =P20*$Q$22 -> 0.000145 | R20: =VLOOKUP($N20,INSUMOS!$B:$D,3,0)*Q20 -> 0.0037265 | S20: 0.000145 | T20: =VLOOKUP($N20,INSUMOS!$B:$D,3,0)*S20 -> 0.0037265 | U20: 11342 | V20: Cloreto de Calcio | W20: 0.0003 | X20: =W20*$X$21 -> 0.0003 | Y20: =VLOOKUP($U20,INSUMOS!$B:$D,3,0)*X20 -> 0.00375
B21: INGREDIENTE | C21: % | D21: 2 | E21: CUSTO | N21: 10718 | O21: Metabissulfito de Sódio | P21: 5e-05 | Q21: =P21*$Q$22 -> 7.25e-06 | R21: =VLOOKUP($N21,INSUMOS!$B:$D,3,0)*Q21 -> 6.4525e-05 | S21: 7.25e-06 | T21: =VLOOKUP($N21,INSUMOS!$B:$D,3,0)*S21 -> 6.4525e-05 | V21: Salmoura total | W21: 1 | X21: 1 | Y21: =SUM(Y16:Y20) -> 1.3456
B22: Água potável | C22: 0.9391 | D22: =C22*$D$28 -> 0.9391 | O22: Salmoura total | P22: 1 | Q22: 0.145 | R22: =SUM(R16:R21) -> 0.18315603 | S22: 0.145 | T22: =SUM(T16:T21) -> 0.18315603
A23: 9794 | B23: Sal | C23: 0.058 | D23: =C23*$D$28 -> 0.058 | E23: =VLOOKUP($A23,INSUMOS!$B:$D,3,0)*D23 -> 1.247
A24: 9789 | B24: Ácido Cítrico | C24: 0.0016 | D24: =C24*$D$28 -> 0.0016 | E24: =VLOOKUP($A24,INSUMOS!$B:$D,3,0)*D24 -> 0.01984 | O24: LINHA DE PRODUTOS - BALDES 2kg
A25: 9511 | B25: Acido Lactico | C25: 0.0005 | D25: =C25*$D$28 -> 0.0005 | E25: =VLOOKUP($A25,INSUMOS!$B:$D,3,0)*D25 -> 0.0076 | O25: INGREDIENTE | P25: % | Q25: 2 | R25: CUSTO
A26: 9792 | B26: Benzoato de Sódio | C26: 0.0003 | D26: =C26*$D$28 -> 0.0003 | E26: =VLOOKUP($A26,INSUMOS!$B:$D,3,0)*D26 -> 0.00852 | O26: Água potável | P26: 0.9404 | Q26: =P26*$Q$33 -> 0.9404
A27: 9790 | B27: Sorbato de Potássio | C27: 0.0005 | D27: =C27*$D$28 -> 0.0005 | E27: =VLOOKUP($A27,INSUMOS!$B:$D,3,0)*D27 -> 0.01285 | N27: 9794 | O27: Sal | P27: 0.054 | Q27: =P27*$Q$33 -> 0.054 | R27: =VLOOKUP($N27,INSUMOS!$B:$D,3,0)*Q27 -> 1.161
B28: Salmoura total | C28: 1 | D28: 1 | E28: =SUM(E21:E27) -> 1.29581 | N28: 9789 | O28: Ácido Cítrico | P28: 0.002 | Q28: =P28*$Q$33 -> 0.002 | R28: =VLOOKUP($N28,INSUMOS!$B:$D,3,0)*Q28 -> 0.0248
N29: 9511 | O29: Acido Lactico | P29: 0.0015 | Q29: =P29*$Q$33 -> 0.0015 | R29: =VLOOKUP($N29,INSUMOS!$B:$D,3,0)*Q29 -> 0.0228
N30: 9792 | O30: Benzoato de Sódio | P30: 0.001 | Q30: =P30*$Q$33 -> 0.001 | R30: =VLOOKUP($N30,INSUMOS!$B:$D,3,0)*Q30 -> 0.0284
N31: 9790 | O31: Sorbato de Potássio | P31: 0.001 | Q31: =P31*$Q$33 -> 0.001 | R31: =VLOOKUP($N31,INSUMOS!$B:$D,3,0)*Q31 -> 0.0257
N32: 10718 | O32: Metabissulfito de Sódio | P32: 5e-05 | Q32: =P32*$Q$33 -> 5e-05 | R32: =VLOOKUP($N32,INSUMOS!$B:$D,3,0)*Q32 -> 0.000445
O33: Salmoura total | P33: 1 | Q33: 1 | R33: =SUM(R27:R32) -> 1.263145

Sheet INSUMOS
B1: INSUMOS
C2: ACIDO | D2: CUSTO UND/KG
B3: 9794 | C3: =VLOOKUP(B3,'Consumo salmoura'!A:J,2,0) -> Sal | D3: 21.5 | E3: KG
B4: 9789 | C4: =VLOOKUP(B4,'Consumo salmoura'!A:J,2,0) -> Ácido Cítrico | D4: 12.4 | E4: KG
B5: 9511 | C5: =VLOOKUP(B5,'Consumo salmoura'!A:J,2,0) -> Acido Lactico | D5: 15.2 | E5: KG
B6: 9792 | C6: =VLOOKUP(B6,'Consumo salmoura'!A:J,2,0) -> Benzoato de Sódio | D6: =5.68*5 -> 28.4 | E6: KG
B7: 9790 | C7: =VLOOKUP(B7,'Consumo salmoura'!A:J,2,0) -> Sorbato de Potássio | D7: =5.14*5 -> 25.7 | E7: KG
B8: 9791 | C8: =VLOOKUP(B8,'Consumo salmoura'!A:J,2,0) -> Acido Ascorbico | D8: =4.2*5 -> 21 | E8: KG
B9: 10718 | C9: Metabissulfito de Sódio | D9: =1.78*5 -> 8.9 | E9: KG
B10: 11342 | C10: Cloreto de Calcio | D10: 12.5 | E10: KG
A11: PROD ACABADO | B11: FILME | F11: GRAMATURA P/ UND
B12: 9809 | C12: FILME TERMOCONTRATIL 600 MM X 80 U | D12: 34 | E12: KG | F12: 0.015
B13: 9829 | C13: FILME AZEITONA VERDE FATIADA SACHET 1010KG | D13: 0.7056 | E13: UND
B14: 9830 | C14: FILME AZEITONA VERDE GRAÚDA SACHET 1010KG | D14: 0.7056 | E14: UND
B15: 9831 | C15: FILME AZEITONA VERDE MEDIA SACHET 1010KG | D15: 0.7056 | E15: UND
B16: 9832 | C16: FILME AZEITONA VERDE MIUDA SACHET 1010KG | D16: 0.7056 | E16: UND
B17: 9833 | C17: FILME CHAMPIGNOM FATIADO SACHET 1010KG | D17: 0.7056 | E17: UND
B18: 9834 | C18: FILME CHAMPIGNOM INTEIRO SACHET 1010KG | D18: 0.7056 | E18: UND
B19: 9835 | C19: FIME AZEITONA VERDE S/CAROÇO SACHET 1010KG | D19: 0.7056 | E19: UND
A20: 9665 | B20: 9827 | C20: FILME AZEITONA FATIADA SACHET 80GR | D20: 57 | E20: KG | F20: 0.006
A21: 9664 | B21: 9828 | C21: FILME AZEITONA S/ CAROÇO SACHET 80GR | D21: 57 | E21: KG | F21: 0.006
A22: 9663 | B22: 9430 | C22: FILME AZEITONA C/ CAROÇO 80 GR | D22: 57 | E22: KG | F22: 0.006
A23: 9361 | B23: 9433 | C23: FILME AZEITONA FATIADA SACHET 120 GR KG | D23: 57 | E23: KG | F23: 0.007
A24: 9360 | B24: 9819 | C24: FILME AZEITONA S/ CAROÇO SACHET 120 GR KG | D24: 57 | E24: KG | F24: 0.007
A25: 9630 | B25: 9821 | C25: FILME AZEITONA C/ CAROÇO 150 GR KG | D25: 57 | E25: KG | F25: 0.007
A26: 9673 | B26: 9823 | C26: FILME CHAMPIGNON INTEIRO 100 GR KG | D26: 57 | E26: KG | F26: 0.006
A27: 10057 | B27: 9824 | C27: FILME CHAMPIGNON FATIADO 100 GR KG | D27: 57 | E27: KG | F27: 0.006
A28: 9565 | B28: 9491 | C28: FiLME AZEITONA C/CAROÇO 50GR | D28: 57 | E28: KG | F28: 0.005
B29: 9820 | C29: FILME AZEITONA RECHEADA SACHET 120 GR KG | D29: 57 | E29: KG | F29: 0.007
B30: 9822 | C30: FILME CEBOLINHA SACHET 120 GR KG | D30: 57 | E30: KG | F30: 0.007
B31: 9825 | C31: FILME CEBOLINHA 50 GR | D31: 57 | E31: KG | F31: 0.004
B32: 9826 | C32: FILME AZEITONA RECHEADA SACHET 80G | D32: 57 | E32: KG | F32: 0.006
A33: 9628 | B33: 11032 | C33: FILME QUEIJO RALADO 40G GROSSO | D33: 57 | E33: KG | F33: 0.004
A34: 9627 | B34: 11032 | C34: FILME QUEIJO RALADO 40G FINO | D34: 57 | E34: KG | F34: 0.004
C35: CAIXAS DE PAPELÃO
B36: 9492 | C36: CAIXA PAPELÃO P/ SACHETS PADRÃO | D36: 2.03 | E36: UND
B37: 9837 | C37: CAIXA PAPELÃO P/ VIDRO 200 GR | D37: 1.83 | E37: UND
B38: 9838 | C38: CAIXA PAPELÃO P/ VIDRO 500 GR | D38: 1.03 | E38: UND
B39: 11125 | C39: CAIXA PAPELÃO QUEIJO RALADO FINO | D39: 0.64 | E39: UND
C40: VIDROS
...

Sheet MP
A1: MATERIA PRIMA | B1: TIPO | C1: CALIBRE | D1: Custo HOJE
A2: AZEITONA COM CAROÇO | B2: MIUDA | C2: 360/600 | D2: 5.9
A3: AZEITONA COM CAROÇO | B3: MEDIA | C3: 200/340 | D3: 9.87
A4: AZEITONA COM CAROÇO | B4: GRAUDA | C4: 80/180 | D4: 11.72
A5: AZEITONA SEM CAROÇO | B5: MEDIA | C5: 200/340 | D5: 11.41
A6: AZEITONA SEM CAROÇO | B6: GRAUDA | C6: 80/180 | D6: 17.3
A7: AZEITONA FATIADA | B7: MEDIA | C7: 200/340 | D7: 11.41
A8: AZEITONA PRETA FATIADA | B8: MEDIA | C8: 200/340 | D8: 16.85 | G8: 600 | H8: 22.9 | I8: =G8*H8 -> 13740
A9: AZEITONA PRETA SEM CAROÇO | B9: MEDIA | C9: 200/340 | D9: 16.85 | G9: 120 | H9: 21.62 | I9: =G9*H9 -> 2594.4
A10: AZEITONA PRETA | B10: GRAUDA | C10: 80/180 | D10: 12.65 | G10: 1980 | H10: 19.08 | I10: =G10*H10 -> 37778.4
A11: CHAMPIGNON FATIADO | D11: 17.5 | G11: 360 | H11: 15.26 | I11: =G11*H11 -> 5493.6
A12: CHAMPIGNON INTEIRO | D12: 19.56
A13: QUEIJO RALADO | B13: FINO | D13: 37 | G13: =SUM(G8:G12) -> 3060 | H13: =I13/G13 -> 19.479216 | I13: =SUM(I8:I12) -> 59606.4
A14: QUEIJO RALADO | B14: GROSSO | D14: 59

Sheet CMV
A3: VIDRO 200/160G | C3: UND MEDIDA | D3: PESO DRENADO | E3: VIDRO | F3: CAIXA | G3: MATERIA PRIMA | H3: SALMOURA | I3: TAMPA | J3: ROTULO | L3: CUSTO
A4: 9645 | B4: AZEITONA VERDE FATIADA VIDRO 160 GR | C4: =VLOOKUP(A4,'[1]PRODUTOS ATIVOS'!$A$1:$AD$1048576,7,0) -> 12 | D4: 0.16 | E4: =INSUMOS!$D$41 -> 0.919 | F4: =INSUMOS!$D$37/CMV!C4 -> 0.1525 | G4: =D4*MP!$D$7 -> 1.8256 | H4: ='Consumo salmoura'!$E$18 -> 0.1806229 | I4: =INSUMOS!$D$46 -> 0.44405 | J4: =INSUMOS!$D$48 -> 0.256 | L4: =SUM(E4:J4) -> 3.7777729
A5: 9646 | B5: AZEITONA VERDE SEM CAROÇO VIDRO 160 GR | C5: =VLOOKUP(A5,'[1]PRODUTOS ATIVOS'!$A$1:$AD$1048576,7,0) -> 12 | D5: 0.16 | E5: =INSUMOS!$D$41 -> 0.919 | F5: =INSUMOS!$D$37/CMV!C5 -> 0.1525 | G5: =D5*MP!$D$5 -> 1.8256 | H5: ='Consumo salmoura'!$E$18 -> 0.1806229 | I5: =INSUMOS!$D$46 -> 0.44405 | J5: =INSUMOS!$D$48 -> 0.256 | L5: =SUM(E5:J5) -> 3.7777729
A6: 9648 | B6: AZEITONA VERDE COM CAROÇO VIDRO 200 GR | C6: =VLOOKUP(A6,'[1]PRODUTOS ATIVOS'!$A$1:$AD$1048576,7,0) -> 12 | D6: 0.2 | E6: =INSUMOS!$D$41 -> 0.919 | F6: =INSUMOS!$D$37/CMV!C6 -> 0.1525 | G6: =D6*MP!$D$3 -> 1.974 | H6: ='Consumo salmoura'!$F$18 -> 0.185 | I6: =INSUMOS!$D$46 -> 0.44405 | J6: =INSUMOS!$D$48 -> 0.256 | L6: =SUM(E6:J6) -> 3.93055
A7: 9651 | B7: CHAMPIGNON INTEIRO VIDRO 200 GRS | C7: =VLOOKUP(A7,'[1]PRODUTOS ATIVOS'!$A$1:$AD$1048576,7,0) -> 12 | D7: 0.2 | E7: =INSUMOS!$D$41 -> 0.919 | F7: =INSUMOS!$D$37/CMV!C7 -> 0.1525 | G7: =D7*MP!$D$12 -> 3.912 | H7: ='Consumo salmoura'!$R$22 -> 0.18315603 | I7: =INSUMOS!$D$46 -> 0.44405 | J7: =INSUMOS!$D$48 -> 0.256 | L7: =SUM(E7:J7) -> 5.866706
A8: 9652 | B8: CHAMPIGNON FATIADO VIDRO 200 GRS | C8: =VLOOKUP(A8,'[1]PRODUTOS ATIVOS'!$A$1:$AD$1048576,7,0) -> 12 | D8: 0.2 | E8: =INSUMOS!$D$41 -> 0.919 | F8: =INSUMOS!$D$37/CMV!C8 -> 0.1525 | G8: =D7*MP!$D$11 -> 3.5 | H8: ='Consumo salmoura'!$R$22 -> 0.18315603 | I8: =INSUMOS!$D$46 -> 0.44405 | J8: =INSUMOS!$D$48 -> 0.256 | L8: =SUM(E8:J8) -> 5.454706
A9: 9653 | B9: AZEITONA VERDE COM CAROÇO GOURMET 200 GR | C9: =VLOOKUP(A9,'[1]PRODUTOS ATIVOS'!$A$1:$AD$1048576,7,0) -> 12 | D9: 0.2 | E9: =INSUMOS!$D$41 -> 0.919 | F9: =INSUMOS!$D$37/CMV!C9 -> 0.1525 | G9: =D9*MP!$D$4 -> 2.344 | H9: ='Consumo salmoura'!$F$18 -> 0.185 | I9: =INSUMOS!$D$46 -> 0.44405 | J9: =INSUMOS!$D$48 -> 0.256 | L9: =SUM(E9:J9) -> 4.30055
A10: 9654 | B10: AZEITONA VERDE SEM CAROÇO GOURMET 160 GR | C10: =VLOOKUP(A10,'[1]PRODUTOS ATIVOS'!$A$1:$AD$1048576,7,0) -> 12 | D10: 0.16 | E10: =INSUMOS!$D$41 -> 0.919 | F10: =INSUMOS!$D$37/CMV!C10 -> 0.1525 | G10: =D10*MP!$D$10 -> 2.024 | H10: ='Consumo salmoura'!$E$18 -> 0.1806229 | I10: =INSUMOS!$D$46 -> 0.44405 | J10: =INSUMOS!$D$48 -> 0.256 | L10: =SUM(E10:J10) -> 3.9761729
A11: 9655 | B11: AZEITONA PRETA C/ CAROÇO GOURMET 200 GR | C11: =VLOOKUP(A11,'[1]PRODUTOS ATIVOS'!$A$1:$AD$1048576,7,0) -> 12 | D11: 0.2 | E11: =INSUMOS!$D$41 -> 0.919 | F11: =INSUMOS!$D$37/CMV!C11 -> 0.1525 | G11: =D11*MP!$D$10 -> 2.53 | H11: ='Consumo salmoura'!AA10 -> 0.248936 | I11: =INSUMOS!$D$46 -> 0.44405 | J11: =INSUMOS!$D$48 -> 0.256 | L11: =SUM(E11:J11) -> 4.550486
A13: VIDRO 500/450/400G | C13: UND MEDIDA | D13: PESO DRENADO | E13: VIDRO | F13: CAIXA | G13: MATERIA PRIMA | H13: SALMOURA | I13: TAMPA | J13: ROTULO | L13: CUSTO
A14: 9357 | B14: AZEITONA VERDE COM CAROÇO VIDRO 500 GR | C14: =VLOOKUP(A14,'[1]PRODUTOS ATIVOS'!$A$1:$AD$1048576,7,0) -> 12 | D14: 0.5 | E14: =INSUMOS!$D$42 -> 1.38 | F14: =INSUMOS!$D$38/CMV!C14 -> 0.085833333 | G14: =D14*MP!$D$3 -> 4.935 | H14: ='Consumo salmoura'!$H$18 -> 0.32 | I14: =INSUMOS!$D$44 -> 0.65966 | J14: =INSUMOS!$D$54 -> 0.276 | L14: =SUM(E14:J14) -> 7.6564933
A15: 9358 | B15: AZEITONA VERDE COM CAROÇO GOURMET 450 GR | C15: =VLOOKUP(A15,'[1]PRODUTOS ATIVOS'!$A$1:$AD$1048576,7,0) -> 12 | D15: 0.45 | E15: =INSUMOS!$D$42 -> 1.38 | F15: =INSUMOS!$D$38/CMV!C15 -> 0.085833333 | G15: =D15*MP!$D$4 -> 5.274 | H15: ='Consumo salmoura'!$H$18 -> 0.32 | I15: =INSUMOS!$D$44 -> 0.65966 | J15: =INSUMOS!$D$54 -> 0.276 | L15: =SUM(E15:J15) -> 7.9954933
A16: 9359 | B16: AZEITONA VERDE SEM CAROÇO GOURMET 400 GR | C16: =VLOOKUP(A16,'[1]PRODUTOS ATIVOS'!$A$1:$AD$1048576,7,0) -> 12 | D16: 0.4 | E16: =INSUMOS!$D$42 -> 1.38 | F16: =INSUMOS!$D$38/CMV!C16 -> 0.085833333 | G16: =D16*MP!$D$6 -> 6.92 | H16: ='Consumo salmoura'!$H$18 -> 0.32 | I16: =INSUMOS!$D$44 -> 0.65966 | J16: =INSUMOS!$D$54 -> 0.276 | L16: =SUM(E16:J16) -> 9.6414933
A17: 9656 | B17: AZEITONA PRETA COM CAROÇO GOURMET 400 GR | C17: =VLOOKUP(A17,'[1]PRODUTOS ATIVOS'!$A$1:$AD$1048576,7,0) -> 12 | D17: 0.4 | E17: =INSUMOS!$D$42 -> 1.38 | F17: =INSUMOS!$D$38/CMV!C17 -> 0.085833333 | G17: =D17*MP!$D$10 -> 5.06 | H17: ='Consumo salmoura'!$Y$10 -> 0.565152 | I17: =INSUMOS!$D$44 -> 0.65966 | J17: =INSUMOS!$D$54 -> 0.276 | L17: =SUM(E17:J17) -> 8.0266453
A19: SACHÊ 80/100G | C19: UND MEDIDA | D19: PESO DRENADO | E19: FILME | F19: CAIXA | G19: MATERIA PRIMA | H19: SALMOURA | L19: CUSTO
A20: 9663 | B20: AZEITONA VERDE COM CAROÇO SACHET 80 GR | C20: =VLOOKUP(A20,'[1]PRODUTOS ATIVOS'!$A$1:$AD$1048576,7,0) -> 30 | D20: 0.08 | E20: =VLOOKUP(A20,INSUMOS!$A$12:$F$34,4,0)*VLOOKUP(CMV!A20,INSUMOS!$A$12:$F$34,6,0) -> 0.342 | F20: =INSUMOS!$D$36/CMV!C20 -> 0.067666667 | G20: =D20*MP!$D$2 -> 0.472 | H20: ='Consumo salmoura'!$E$10 -> 0.0870174 | L20: =SUM(E20:J20) -> 0.96868407
A21: 9664 | B21: AZEITONA VERDE SEM CAROÇO SACHET 80 GR | C21: =VLOOKUP(A21,'[1]PRODUTOS ATIVOS'!$A$1:$AD$1048576,7,0) -> 30 | D21: 0.08 | E21: =VLOOKUP(A21,INSUMOS!$A$12:$F$34,4,0)*VLOOKUP(CMV!A21,INSUMOS!$A$12:$F$34,6,0) -> 0.342 | F21: =INSUMOS!$D$36/CMV!C21 -> 0.067666667 | G21: =D21*MP!$D$5 -> 0.9128 | H21: ='Consumo salmoura'!$E$10 -> 0.0870174 | L21: =SUM(E21:J21) -> 1.4094841
A22: 9665 | B22: AZEITONA VERDE FATIADA SACHET 80 GR | C22: =VLOOKUP(A22,'[1]PRODUTOS ATIVOS'!$A$1:$AD$1048576,7,0) -> 30 | D22: 0.08 | E22: =VLOOKUP(A22,INSUMOS!$A$12:$F$34,4,0)*VLOOKUP(CMV!A22,INSUMOS!$A$12:$F$34,6,0) -> 0.342 | F22: =INSUMOS!$D$36/CMV!C22 -> 0.067666667 | G22: =D22*MP!$D$7 -> 0.9128 | H22: ='Consumo salmoura'!$E$10 -> 0.0870174 | L22: =SUM(E22:J22) -> 1.4094841
A23: 9673 | B23: CHAMPIGNON INTEIRO SACHET 100 GR | C23: =VLOOKUP(A23,'[1]PRODUTOS ATIVOS'!$A$1:$AD$1048576,7,0) -> 30 | D23: 0.1 | E23: =VLOOKUP(A23,INSUMOS!$A$12:$F$34,4,0)*VLOOKUP(CMV!A23,INSUMOS!$A$12:$F$34,6,0) -> 0.342 | F23: =INSUMOS!$D$36/CMV!C23 -> 0.067666667 | G23: =D23*MP!$D$12 -> 1.956 | H23: ='Consumo salmoura'!$R$11 -> 0.08842015 | L23: =SUM(E23:J23) -> 2.4540868
A24: 10057 | B24: CHAMPIGNON FATIADO SACHET 100 GR | C24: =VLOOKUP(A24,'[1]PRODUTOS ATIVOS'!$A$1:$AD$1048576,7,0) -> 30 | D24: 0.1 | E24: =VLOOKUP(A24,INSUMOS!$A$12:$F$34,4,0)*VLOOKUP(CMV!A24,INSUMOS!$A$12:$F$34,6,0) -> 0.342 | F24: =INSUMOS!$D$36/CMV!C24 -> 0.067666667 | G24: =D23*MP!$D$11 -> 1.75 | H24: ='Consumo salmoura'!$R$11 -> 0.08842015 | L24: =SUM(E24:J24) -> 2.2480868
A26: SACHÊ 120/150/50G | C26: UND MEDIDA | D26: PESO DRENADO | E26: FILME | F26: CAIXA | G26: MATERIA PRIMA | H26: SALMOURA | L26: CUSTO
A27: 9360 | B27: AZEITONA VERDE SEM CAROÇO SACHET 120 GR | C27: =VLOOKUP(A27,'[1]PRODUTOS ATIVOS'!$A$1:$AD$1048576,7,0) -> 18 | D27: 0.12 | E27: =VLOOKUP(A27,INSUMOS!$A$12:$F$34,4,0)*VLOOKUP(CMV!A27,INSUMOS!$A$12:$F$34,6,0) -> 0.399 | F27: =INSUMOS!$D$36/CMV!C27 -> 0.11277778 | G27: =D27*MP!$D$5 -> 1.3692 | H27: ='Consumo salmoura'!$F$10 -> 0.15 | L27: =SUM(E27:J27) -> 2.0309778
A28: 9361 | B28: AZEITONA VERDE FATIADA SACHET 120 GR | C28: =VLOOKUP(A28,'[1]PRODUTOS ATIVOS'!$A$1:$AD$1048576,7,0) -> 18 | D28: 0.12 | E28: =VLOOKUP(A28,INSUMOS!$A$12:$F$34,4,0)*VLOOKUP(CMV!A28,INSUMOS!$A$12:$F$34,6,0) -> 0.399 | F28: =INSUMOS!$D$36/CMV!C28 -> 0.11277778 | G28: =D28*MP!$D$7 -> 1.3692 | H28: ='Consumo salmoura'!$F$10 -> 0.15 | L28: =SUM(E28:J28) -> 2.0309778
A29: 9630 | B29: AZEITONA VERDE COM CAROÇO SACHET 150 GR | C29: =VLOOKUP(INSUMOS!A25,'[1]PRODUTOS ATIVOS'!$A$1:$AD$1048576,7,0) -> 18 | D29: 0.15 | E29: =VLOOKUP(A29,INSUMOS!$A$12:$F$34,4,0)*VLOOKUP(CMV!A29,INSUMOS!$A$12:$F$34,6,0) -> 0.399 | F29: =INSUMOS!$D$36/CMV!C29 -> 0.11277778 | G29: =D29*MP!$D$3 -> 1.4805 | H29: ='Consumo salmoura'!I10 -> 0.1160232 | L29: =SUM(E29:J29) -> 2.108301
A30: 9565 | B30: AZEITONA VERDE COM CAROÇO SACHET 50 GR | C30: =VLOOKUP(INSUMOS!A28,'[1]PRODUTOS ATIVOS'!$A$1:$AD$1048576,7,0) -> 36 | D30: 0.05 | E30: =VLOOKUP(A30,INSUMOS!$A$12:$F$34,4,0)*VLOOKUP(CMV!A30,INSUMOS!$A$12:$F$34,6,0) -> 0.285 | F30: =INSUMOS!$D$36/CMV!C30 -> 0.056388889 | G30: =D30*MP!$D$2 -> 0.295 | H30: ='Consumo salmoura'!$M$10 -> 0.1160232 | L30: =SUM(E30:J30) -> 0.75241209
A32: SACHÊ 1,010KG | C32: UND MEDIDA | D32: PESO DRENADO | E32: FILME | F32: CAIXA | G32: MATERIA PRIMA | H32: SALMOURA | L32: CUSTO
A33: 9674 | B33: AZEITONA VERDE FATIADA SACHET 1,010 KG | C33: =VLOOKUP(A33,'[1]PRODUTOS ATIVOS'!$A$1:$AD$1048576,7,0) -> 6 | D33: 1.01 | E33: =INSUMOS!D13 -> 0.7056 | F33: =INSUMOS!$D$36/CMV!C33 -> 0.33833333 | G33: =D33*MP!$D$7 -> 11.5241 | H33: ='Consumo salmoura'!$J$10 -> 0.59 | L33: =SUM(E33:J33) -> 13.158033
A34: 9675 | B34: AZEITONA VERDE S/ CAROÇO SACHET 1,010 KG | C34: =VLOOKUP(A34,'[1]PRODUTOS ATIVOS'!$A$1:$AD$1048576,7,0) -> 6 | D34: 1.01 | E34: =INSUMOS!D14 -> 0.7056 | F34: =INSUMOS!$D$36/CMV!C34 -> 0.33833333 | G34: =D34*MP!$D$5 -> 11.5241 | H34: ='Consumo salmoura'!$J$10 -> 0.59 | L34: =SUM(E34:J34) -> 13.158033
A35: 9677 | B35: AZEITONA VERDE GRAUDA SACHET 1,010 KG | C35: =VLOOKUP(A35,'[1]PRODUTOS ATIVOS'!$A$1:$AD$1048576,7,0) -> 6 | D35: 1.01 | E35: =INSUMOS!D15 -> 0.7056 | F35: =INSUMOS!$D$36/CMV!C35 -> 0.33833333 | G35: =D35*MP!$D$4 -> 11.8372 | H35: ='Consumo salmoura'!$J$10 -> 0.59 | L35: =SUM(E35:J35) -> 13.471133
A36: 9678 | B36: AZEITONA VERDE MEDIA SACHET 1,010 KG | C36: =VLOOKUP(A36,'[1]PRODUTOS ATIVOS'!$A$1:$AD$1048576,7,0) -> 6 | D36: 1.01 | E36: =INSUMOS!D16 -> 0.7056 | F36: =INSUMOS!$D$36/CMV!C36 -> 0.33833333 | G36: =D36*MP!$D$3 -> 9.9687 | H36: ='Consumo salmoura'!$J$10 -> 0.59 | L36: =SUM(E36:J36) -> 11.602633
A37: 9679 | B37: AZEITONA VERDE MIUDA SACHET 1,010 KG | C37: =VLOOKUP(A37,'[1]PRODUTOS ATIVOS'!$A$1:$AD$1048576,7,0) -> 6 | D37: 1.01 | E37: =INSUMOS!D17 -> 0.7056 | F37: =INSUMOS!$D$36/CMV!C37 -> 0.33833333 | G37: =D37*MP!$D$2 -> 5.959 | H37: ='Consumo salmoura'!$J$10 -> 0.59 | L37: =SUM(E37:J37) -> 7.5929333
A38: 9680 | B38: CHAMPIGNON INTEIRO SACHET 1,010 KG | C38: =VLOOKUP(A38,'[1]PRODUTOS ATIVOS'!$A$1:$AD$1048576,7,0) -> 6 | D38: 1.01 | E38: =INSUMOS!D18 -> 0.7056 | F38: =INSUMOS!$D$36/CMV!C38 -> 0.33833333 | G38: =D38*MP!$D$12 -> 19.7556 | H38: ='Consumo salmoura'!$T$11 -> 0.74525555 | L38: =SUM(E38:J38) -> 21.544789
A39: 9681 | B39: CHAMPIGNON FATIADO SACHET 1,010 KG | C39: =VLOOKUP(A39,'[1]PRODUTOS ATIVOS'!$A$1:$AD$1048576,7,0) -> 6 | D39: 1.01 | E39: =INSUMOS!D19 -> 0.7056 | F39: =INSUMOS!$D$36/CMV!C39 -> 0.33833333 | G39: =D38*MP!$D$11 -> 17.675 | H39: ='Consumo salmoura'!$T$11 -> 0.74525555 | L39: =SUM(E39:J39) -> 19.464189
A41: QUEIJO RALADO | C41: UND MEDIDA | D41: PESO DRENADO | E41: FILME | F41: CAIXA | G41: MATERIA PRIMA | H41: SALMOURA | L41: CUSTO
A42: 9627 | B42: QUEIJO PARMESÃO RALADO FINO SACHET 40 GR | C42: =VLOOKUP(A42,'[1]PRODUTOS ATIVOS'!$A$1:$AD$1048576,7,0) -> 25 | D42: 0.04 | E42: =VLOOKUP(A42,INSUMOS!$A$12:$F$34,4,0)*VLOOKUP(CMV!A42,INSUMOS!$A$12:$F$34,6,0) -> 0.228 | F42: =INSUMOS!$D$39/CMV!$C$42 -> 0.0256 | G42: =D42*MP!D13 -> 1.48 | H42: 0 | L42: =SUM(E42:J42) -> 1.7336
A43: 9628 | B43: QUEIJO PARMESÃO RALADO FIAPO SACHET 40 GR | C43: =VLOOKUP(A43,'[1]PRODUTOS ATIVOS'!$A$1:$AD$1048576,7,0) -> 25 | D43: 0.04 | E43: =VLOOKUP(A43,INSUMOS!$A$12:$F$34,4,0)*VLOOKUP(CMV!A43,INSUMOS!$A$12:$F$34,6,0) -> 0.228 | F43: =INSUMOS!$D$39/CMV!$C$42 -> 0.0256 | G43: =D43*MP!D14 -> 2.36 | H43: 0 | L43: =SUM(E43:J43) -> 2.6136
A45: BALDE 2KG | C45: UND MEDIDA | D45: PESO DRENADO | E45: BALDE | F45: TAMPA | G45: MATERIA PRIMA | H45: SALMOURA | L45: CUSTO
A46: 9682 | B46: AZEITONA VERDE FATIADA BALDE 2 KG | C46: =VLOOKUP(A46,'[1]PRODUTOS ATIVOS'!$A$1:$AD$1048576,7,0) -> 2 | D46: 2 | E46: =INSUMOS!$D$64 -> 3.67 | F46: =INSUMOS!$D$45 -> 1.58 | G46: =D46*MP!$D$7 -> 22.82 | H46: ='Consumo salmoura'!$E$28 -> 1.29581 | L46: =SUM(E46:J46) -> 29.36581
A47: 9685 | B47: AZEITONA VERDE S/ CAROÇO BALDE 2 KG | C47: =VLOOKUP(A47,'[1]PRODUTOS ATIVOS'!$A$1:$AD$1048576,7,0) -> 2 | D47: 2 | E47: =INSUMOS!$D$64 -> 3.67 | F47: =INSUMOS!$D$45 -> 1.58 | G47: =D47*MP!$D$5 -> 22.82 | H47: ='Consumo salmoura'!$E$28 -> 1.29581 | L47: =SUM(E47:J47) -> 29.36581
A48: 9688 | B48: AZEITONA PRETA BALDE 2 KG | C48: =VLOOKUP(A48,'[1]PRODUTOS ATIVOS'!$A$1:$AD$1048576,7,0) -> 2 | D48: 2 | E48: =INSUMOS!$D$64 -> 3.67 | F48: =INSUMOS!$D$45 -> 1.58 | G48: =D48*MP!$D$10 -> 25.3 | H48: ='Consumo salmoura'!$Y$21 -> 1.3456 | L48: =SUM(E48:J48) -> 31.8956
...

Sheet COMPARATIVO CUSTO ANTIGO x NOVO
A3: VIDRO 200/160G | D3: CUSTO ANTIGO | E3: CUSTO NOVO | G3: DIFERENÇA
A4: 9645 | B4: AZEITONA VERDE FATIADA VIDRO 160 GR | D4: =VLOOKUP(A4,[2]CMV!$B$1:$O$1048576,14,0) -> 4.75418 | E4: 4.5521729 | G4: =1-(D4/E4) -> -0.044375981
A5: 9646 | B5: AZEITONA VERDE SEM CAROÇO VIDRO 160 GR | D5: =VLOOKUP(A5,[2]CMV!$B$1:$O$1048576,14,0) -> 4.55168 | E5: 4.5521729 | G5: =1-(D5/E5) -> 0.00010826917
A6: 9648 | B6: AZEITONA VERDE COM CAROÇO VIDRO 200 GR | D6: =VLOOKUP(A6,[2]CMV!$B$1:$O$1048576,14,0) -> 3.87248 | E6: 3.52655 | G6: =1-(D6/E6) -> -0.098093048
A7: 9651 | B7: CHAMPIGNON INTEIRO VIDRO 200 GRS | D7: =VLOOKUP(A7,[2]CMV!$B$1:$O$1048576,14,0) -> 5.0590258 | E7: 5.866706 | G7: =1-(D7/E7) -> 0.13767184
A8: 9652 | B8: CHAMPIGNON FATIADO VIDRO 200 GRS | D8: =VLOOKUP(A8,[2]CMV!$B$1:$O$1048576,14,0) -> 5.7986092 | E8: 5.454706 | G8: =1-(D8/E8) -> -0.063047055
A9: 9653 | B9: AZEITONA VERDE COM CAROÇO GOURMET 200 GR | D9: =VLOOKUP(A9,[2]CMV!$B$1:$O$1048576,14,0) -> 4.49248 | E9: 4.37055 | G9: =1-(D9/E9) -> -0.0278981
A10: 9654 | B10: AZEITONA VERDE SEM CAROÇO GOURMET 160 GR | D10: =VLOOKUP(A10,[2]CMV!$B$1:$O$1048576,14,0) -> 4.72448 | E10: 4.0369729 | G10: =1-(D10/E10) -> -0.17030264
A11: 9655 | B11: AZEITONA PRETA C/ CAROÇO GOURMET 200 GR | D11: =VLOOKUP(A11,[2]CMV!$B$1:$O$1048576,14,0) -> 5.45648 | E11: 4.626486 | G11: =1-(D11/E11) -> -0.17940053
A13: VIDRO 500/450/400G | D13: CUSTO ANTIGO | E13: CUSTO NOVO | G13: DIFERENÇA
A14: 9357 | B14: AZEITONA VERDE COM CAROÇO VIDRO 500 GR | D14: =VLOOKUP(A14,[2]CMV!$B$1:$O$1048576,14,0) -> 8.6731142 | E14: 6.6464933 | G14: =1-(D14/E14) -> -0.30491581
A15: 9358 | B15: AZEITONA VERDE COM CAROÇO GOURMET 450 GR | D15: =VLOOKUP(A15,[2]CMV!$B$1:$O$1048576,14,0) -> 8.3641142 | E15: 8.1529933 | G15: =1-(D15/E15) -> -0.02589489
A16: 9359 | B16: AZEITONA VERDE SEM CAROÇO GOURMET 400 GR | D16: =VLOOKUP(A16,[2]CMV!$B$1:$O$1048576,14,0) -> 9.5781142 | E16: 9.6414933 | G16: =1-(D16/E16) -> 0.0065735806
A17: 9656 | B17: AZEITONA PRETA COM CAROÇO GOURMET 400 GR | D17: =VLOOKUP(A17,[2]CMV!$B$1:$O$1048576,14,0) -> 10.947314 | E17: 8.1786453 | G17: =1-(D17/E17) -> -0.33852414
A19: SACHÊ 80/100G | D19: CUSTO ANTIGO | E19: CUSTO NOVO | G19: DIFERENÇA
A20: 9663 | B20: AZEITONA VERDE COM CAROÇO SACHET 80 GR | D20: =VLOOKUP(A20,[2]CMV!$B$1:$O$1048576,14,0) -> 1.0010961 | E20: 1.1046841 | G20: =1-(D20/E20) -> 0.093771616
A21: 9664 | B21: AZEITONA VERDE SEM CAROÇO SACHET 80 GR | D21: =VLOOKUP(A21,[2]CMV!$B$1:$O$1048576,14,0) -> 1.7397961 | E21: 1.7966841 | G21: =1-(D21/E21) -> 0.031662779
A22: 9665 | B22: AZEITONA VERDE FATIADA SACHET 80 GR | D22: =VLOOKUP(A22,[2]CMV!$B$1:$O$1048576,14,0) -> 1.7397961 | E22: 1.7966841 | G22: =1-(D22/E22) -> 0.031662779
A23: 9673 | B23: CHAMPIGNON INTEIRO SACHET 100 GR | D23: =VLOOKUP(A23,[2]CMV!$B$1:$O$1048576,14,0) -> 2.9258277 | E23: 2.4540868 | G23: =1-(D23/E23) -> -0.19222666
A24: 10057 | B24: CHAMPIGNON FATIADO SACHET 100 GR | D24: =VLOOKUP(A24,[2]CMV!$B$1:$O$1048576,14,0) -> 2.4450986 | E24: 2.2480868 | G24: =1-(D24/E24) -> -0.08763529
A26: SACHÊ 120/150/50G | D26: CUSTO ANTIGO | E26: CUSTO NOVO | G26: DIFERENÇA
A27: 9360 | B27: AZEITONA VERDE SEM CAROÇO SACHET 120 GR | D27: =VLOOKUP(A27,[2]CMV!$B$1:$O$1048576,14,0) -> 2.4679748 | E27: 2.6117778 | G27: =1-(D27/E27) -> 0.055059409
A28: 9361 | B28: AZEITONA VERDE FATIADA SACHET 120 GR | D28: =VLOOKUP(A28,[2]CMV!$B$1:$O$1048576,14,0) -> 2.4679748 | E28: 2.6117778 | G28: =1-(D28/E28) -> 0.055059409
A29: 9630 | B29: AZEITONA VERDE COM CAROÇO SACHET 150 GR | D29: =VLOOKUP(A29,[2]CMV!$B$1:$O$1048576,14,0) -> 1.9386548 | E29: 1.805301 | G29: =1-(D29/E29) -> -0.073867938
A30: 9565 | B30: AZEITONA VERDE COM CAROÇO SACHET 50 GR | D30: =VLOOKUP(A30,[2]CMV!$B$1:$O$1048576,14,0) -> 0.74248595 | E30: 0.83741209 | G30: =1-(D30/E30) -> 0.11335654
A32: SACHÊ 1,010KG | D32: CUSTO ANTIGO | E32: CUSTO NOVO | G32: DIFERENÇA
A33: 9674 | B33: AZEITONA VERDE FATIADA SACHET 1,010 KG | D33: =VLOOKUP(A33,[2]CMV!$B$1:$O$1048576,14,0) -> 17.501162 | E33: 18.046433 | G33: =1-(D33/E33) -> 0.030214909
A34: 9675 | B34: AZEITONA VERDE S/ CAROÇO SACHET 1,010 KG | D34: =VLOOKUP(A34,[2]CMV!$B$1:$O$1048576,14,0) -> 17.501162 | E34: 18.046433 | G34: =1-(D34/E34) -> 0.030214909
A35: 9677 | B35: AZEITONA VERDE GRAUDA SACHET 1,010 KG | D35: =VLOOKUP(A35,[2]CMV!$B$1:$O$1048576,14,0) -> 13.877788 | E35: 13.824633 | G35: =1-(D35/E35) -> -0.0038449383
A36: 9678 | B36: AZEITONA VERDE MEDIA SACHET 1,010 KG | D36: =VLOOKUP(A36,[2]CMV!$B$1:$O$1048576,14,0) -> 10.794762 | E36: 9.5624333 | G36: =1-(D36/E36) -> -0.12887187
A37: 9679 | B37: AZEITONA VERDE MIUDA SACHET 1,010 KG | D37: =VLOOKUP(A37,[2]CMV!$B$1:$O$1048576,14,0) -> 8.512162 | E37: 9.3099333 | G37: =1-(D37/E37) -> 0.085690338
A38: 9680 | B38: CHAMPIGNON INTEIRO SACHET 1,010 KG | D38: =VLOOKUP(A38,[2]CMV!$B$1:$O$1048576,14,0) -> 20.79292 | E38: 21.544789 | G38: =1-(D38/E38) -> 0.034897931
A39: 9681 | B39: CHAMPIGNON FATIADO SACHET 1,010 KG | D39: =VLOOKUP(A39,[2]CMV!$B$1:$O$1048576,14,0) -> 17.058024 | E39: 19.464189 | G39: =1-(D39/E39) -> 0.12362007
A41: QUEIJO RALADO | D41: CUSTO ANTIGO | E41: CUSTO NOVO | G41: DIFERENÇA
A42: 9627 | B42: QUEIJO PARMESÃO RALADO FINO SACHET 40 GR | D42: =VLOOKUP(A42,[2]CMV!$B$1:$O$1048576,14,0) -> 1.5175 | E42: 1.6536 | G42: =1-(D42/E42) -> 0.082305273
A43: 9628 | B43: QUEIJO PARMESÃO RALADO FIAPO SACHET 40 GR | D43: =VLOOKUP(A43,[2]CMV!$B$1:$O$1048576,14,0) -> 2.4775 | E43: 2.6136 | G43: =1-(D43/E43) -> 0.052073768
A45: BALDE 2KG | D45: CUSTO ANTIGO | E45: CUSTO NOVO | G45: DIFERENÇA
A46: 9682 | B46: AZEITONA VERDE FATIADA BALDE 2 KG | D46: =VLOOKUP(A46,[2]CMV!$B$1:$O$1048576,14,0) -> 36.743846 | E46: 39.05081 | G46: =1-(D46/E46) -> 0.059075958
A47: 9685 | B47: AZEITONA VERDE S/ CAROÇO BALDE 2 KG | D47: =VLOOKUP(A47,[2]CMV!$B$1:$O$1048576,14,0) -> 36.726164 | E47: 39.05081 | G47: =1-(D47/E47) -> 0.059528752
A48: 9688 | B48: AZEITONA PRETA BALDE 2 KG | D48: =VLOOKUP(A48,[2]CMV!$B$1:$O$1048576,14,0) -> 50.796454 | E48: 32.6606 | G48: =1-(D48/E48) -> -0.55528233
...

Sheet TABELA MÃE
E2: UNIDADES | L2: CAIXA
A3: CÓD | B3: COD SANKHYA | C3: DESCRIÇÃO DO PRODUTO | E3: CUSTO NOVO | F3: MARGEM | G3: VAREJO | H3: ATACAREJO | I3: ATACADO | J3: DISTRIBUIDOR | L3: CUSTO UND | M3: PV VAREJO | N3: PV ATACAREJO | O3: PV ATACADO GENERALISTA | P3: PV DISTRIBUIDOR
A7: 1001 | B7: =VLOOKUP(A7,'[3]PRODUTOS ATIVOS'!$A$1:$AE$1048576,2,0) -> 9627 | C7: QUEIJO PARMESÃO RALADO FINO SACHET 40 GR | D7: 25 | E7: =VLOOKUP(B7,CMV!A:L,12,0) -> 1.7336 | F7: 0.45 | G7: =E7/(1-F7) -> 3.152 | H7: =G7*0.965 -> 3.04168 | I7: =G7*0.9 -> 2.8368 | J7: =G7*0.86 -> 2.71072 | L7: =E7*D7 -> 43.34 | M7: =$D$7*G7 -> 78.8 | N7: =$D7*H7 -> 76.042 | O7: =$D$7*I7 -> 70.92 | P7: =$D$7*J7 -> 67.768
A8: 1002 | B8: =VLOOKUP(A8,'[3]PRODUTOS ATIVOS'!$A$1:$AE$1048576,2,0) -> 9628 | C8: QUEIJO PARMESÃO RALADO FIAPO SACHET 40 GR | D8: 25 | E8: =VLOOKUP(B8,CMV!A:L,12,0) -> 2.6136 | F8: 0.45 | G8: =E8/(1-F8) -> 4.752 | H8: =G8*0.965 -> 4.58568 | I8: =G8*0.9 -> 4.2768 | J8: =G8*0.86 -> 4.08672 | L8: =E8*D8 -> 65.34 | M8: =$D$7*G8 -> 118.8 | N8: =$D8*H8 -> 114.642 | O8: =$D$7*I8 -> 106.92 | P8: =$D$7*J8 -> 102.168
A10: 2001 | B10: =VLOOKUP(A10,'[3]PRODUTOS ATIVOS'!$A$1:$AE$1048576,2,0) -> 9645 | C10: AZEITONA VERDE FATIADA VIDRO 160 GR | D10: 12 | E10: =VLOOKUP(B10,CMV!A:L,12,0) -> 3.7777729 | F10: 0.45 | G10: =E10/(1-F10) -> 6.868678 | H10: =G10*0.965 -> 6.6282743 | I10: =G10*0.9 -> 6.1818102 | J10: =G10*0.86 -> 5.9070631 | L10: =E10*D10 -> 45.333275 | M10: =$D10*G10 -> 82.424136 | N10: =$D10*H10 -> 79.539291 | O10: =$D10*I10 -> 74.181722 | P10: =$D10*J10 -> 70.884757
A11: 2002 | B11: =VLOOKUP(A11,'[3]PRODUTOS ATIVOS'!$A$1:$AE$1048576,2,0) -> 9646 | C11: AZEITONA VERDE SEM CAROÇO VIDRO 160 GR | D11: 12 | E11: =VLOOKUP(B11,CMV!A:L,12,0) -> 3.7777729 | F11: 0.45 | G11: =E11/(1-F11) -> 6.868678 | H11: =G11*0.965 -> 6.6282743 | I11: =G11*0.9 -> 6.1818102 | J11: =G11*0.86 -> 5.9070631 | L11: =E11*D11 -> 45.333275 | M11: =$D11*G11 -> 82.424136 | N11: =$D11*H11 -> 79.539291 | O11: =$D11*I11 -> 74.181722 | P11: =$D11*J11 -> 70.884757
A12: 2004 | B12: =VLOOKUP(A12,'[3]PRODUTOS ATIVOS'!$A$1:$AE$1048576,2,0) -> 9648 | C12: AZEITONA VERDE COM CAROÇO VIDRO 200 GR | D12: 12 | E12: =VLOOKUP(B12,CMV!A:L,12,0) -> 3.93055 | F12: 0.45 | G12: =E12/(1-F12) -> 7.1464545 | H12: =G12*0.965 -> 6.8963286 | I12: =G12*0.9 -> 6.4318091 | J12: =G12*0.86 -> 6.1459509 | L12: =E12*D12 -> 47.1666 | M12: =$D12*G12 -> 85.757455 | N12: =$D12*H12 -> 82.755944 | O12: =$D12*I12 -> 77.181709 | P12: =$D12*J12 -> 73.751411
A13: 2031 | B13: =VLOOKUP(A13,'[3]PRODUTOS ATIVOS'!$A$1:$AE$1048576,2,0) -> 9651 | C13: CHAMPIGNON INTEIRO VIDRO 200 GRS | D13: 12 | E13: =VLOOKUP(B13,CMV!A:L,12,0) -> 5.866706 | F13: 0.45 | G13: =E13/(1-F13) -> 10.666738 | H13: =G13*0.965 -> 10.293402 | I13: =G13*0.9 -> 9.6000644 | J13: =G13*0.86 -> 9.1733949 | L13: =E13*D13 -> 70.400472 | M13: =$D13*G13 -> 128.00086 | N13: =$D13*H13 -> 123.52083 | O13: =$D13*I13 -> 115.20077 | P13: =$D13*J13 -> 110.08074
A14: 2032 | B14: =VLOOKUP(A14,'[3]PRODUTOS ATIVOS'!$A$1:$AE$1048576,2,0) -> 9652 | C14: CHAMPIGNON FATIADO VIDRO 200 GRS | D14: 12 | E14: =VLOOKUP(B14,CMV!A:L,12,0) -> 5.454706 | F14: 0.45 | G14: =E14/(1-F14) -> 9.9176473 | H14: =G14*0.965 -> 9.5705297 | I14: =G14*0.9 -> 8.9258826 | J14: =G14*0.86 -> 8.5291767 | L14: =E14*D14 -> 65.456472 | M14: =$D14*G14 -> 119.01177 | N14: =$D14*H14 -> 114.84636 | O14: =$D14*I14 -> 107.11059 | P14: =$D14*J14 -> 102.35012
A15: 2005 | B15: =VLOOKUP(A15,'[3]PRODUTOS ATIVOS'!$A$1:$AE$1048576,2,0) -> 9357 | C15: AZEITONA VERDE COM CAROÇO VIDRO 500 GR | D15: 12 | E15: =VLOOKUP(B15,CMV!A:L,12,0) -> 7.6564933 | F15: 0.45 | G15: =E15/(1-F15) -> 13.920897 | H15: =G15*0.965 -> 13.433666 | I15: =G15*0.9 -> 12.528807 | J15: =G15*0.86 -> 11.971971 | L15: =E15*D15 -> 91.87792 | M15: =$D15*G15 -> 167.05076 | N15: =$D15*H15 -> 161.20399 | O15: =$D15*I15 -> 150.34569 | P15: =$D15*J15 -> 143.66366
A16: 2021 | B16: =VLOOKUP(A16,'[3]PRODUTOS ATIVOS'!$A$1:$AE$1048576,2,0) -> 9358 | C16: AZEITONA VERDE COM CAROÇO GOURMET 450 GR | D16: 12 | E16: =VLOOKUP(B16,CMV!A:L,12,0) -> 7.9954933 | F16: 0.45 | G16: =E16/(1-F16) -> 14.537261 | H16: =G16*0.965 -> 14.028456 | I16: =G16*0.9 -> 13.083535 | J16: =G16*0.86 -> 12.502044 | L16: =E16*D16 -> 95.94592 | M16: =$D16*G16 -> 174.44713 | N16: =$D16*H16 -> 168.34148 | O16: =$D16*I16 -> 157.00241 | P16: =$D16*J16 -> 150.02453
A17: 2022 | B17: =VLOOKUP(A17,'[3]PRODUTOS ATIVOS'!$A$1:$AE$1048576,2,0) -> 9359 | C17: AZEITONA VERDE SEM CAROÇO GOURMET 400 GR | D17: 12 | E17: =VLOOKUP(B17,CMV!A:L,12,0) -> 9.6414933 | F17: 0.45 | G17: =E17/(1-F17) -> 17.529988 | H17: =G17*0.965 -> 16.916438 | I17: =G17*0.9 -> 15.776989 | J17: =G17*0.86 -> 15.07579 | L17: =E17*D17 -> 115.69792 | M17: =$D17*G17 -> 210.35985 | N17: =$D17*H17 -> 202.99726 | O17: =$D17*I17 -> 189.32387 | P17: =$D17*J17 -> 180.90947
A18: 2024 | B18: =VLOOKUP(A18,'[3]PRODUTOS ATIVOS'!$A$1:$AE$1048576,2,0) -> 9656 | C18: AZEITONA PRETA COM CAROÇO GOURMET 400 GR | D18: 12 | E18: =VLOOKUP(B18,CMV!A:L,12,0) -> 8.0266453 | F18: 0.45 | G18: =E18/(1-F18) -> 14.593901 | H18: =G18*0.965 -> 14.083114 | I18: =G18*0.9 -> 13.134511 | J18: =G18*0.86 -> 12.550755 | L18: =E18*D18 -> 96.319744 | M18: =$D18*G18 -> 175.12681 | N18: =$D18*H18 -> 168.99737 | O18: =$D18*I18 -> 157.61413 | P18: =$D18*J18 -> 150.60905
B19: 9653 | C19: AZEITONA VERDE COM CAROÇO GOURMET 200 GR | D19: 12 | E19: =VLOOKUP(B19,CMV!A:L,12,0) -> 4.30055 | F19: 0.45 | G19: =E19/(1-F19) -> 7.8191818 | H19: =G19*0.965 -> 7.5455105 | I19: =G19*0.9 -> 7.0372636 | J19: =G19*0.86 -> 6.7244964 | L19: =E19*D19 -> 51.6066 | M19: =$D19*G19 -> 93.830182 | N19: =$D19*H19 -> 90.546125 | O19: =$D19*I19 -> 84.447164 | P19: =$D19*J19 -> 80.693956
B20: 9654 | C20: AZEITONA VERDE SEM CAROÇO GOURMET 160 GR | D20: 12 | E20: =VLOOKUP(B20,CMV!A:L,12,0) -> 3.9761729 | F20: 0.45 | G20: =E20/(1-F20) -> 7.2294053 | H20: =G20*0.965 -> 6.9763761 | I20: =G20*0.9 -> 6.5064647 | J20: =G20*0.86 -> 6.2172885 | L20: =E20*D20 -> 47.714075 | M20: =$D20*G20 -> 86.752863 | N20: =$D20*H20 -> 83.716513 | O20: =$D20*I20 -> 78.077577 | P20: =$D20*J20 -> 74.607462
A21: 2017 | B21: =VLOOKUP(A21,'[3]PRODUTOS ATIVOS'!$A$1:$AE$1048576,2,0) -> 9655 | C21: AZEITONA PRETA C/ CAROÇO GOURMET 200 GR | D21: 12 | E21: =VLOOKUP(B21,CMV!A:L,12,0) -> 4.550486 | F21: 0.45 | G21: =E21/(1-F21) -> 8.2736109 | H21: =G21*0.965 -> 7.9840345 | I21: =G21*0.9 -> 7.4462498 | J21: =G21*0.86 -> 7.1153054 | L21: =E21*D21 -> 54.605832 | M21: =$D21*G21 -> 99.283331 | N21: =$D21*H21 -> 95.808414 | O21: =$D21*I21 -> 89.354998 | P21: =$D21*J21 -> 85.383665 | Q21: =M21*0.8 -> 79.426665
A23: 2006 | B23: =VLOOKUP(A23,'[3]PRODUTOS ATIVOS'!$A$1:$AE$1048576,2,0) -> 9663 | C23: AZEITONA VERDE COM CAROÇO SACHET 80 GR | D23: 30 | E23: =VLOOKUP(B23,CMV!A:L,12,0) -> 0.96868407 | F23: 0.45 | G23: =E23/(1-F23) -> 1.7612438 | H23: =G23*0.965 -> 1.6996002 | I23: =G23*0.9 -> 1.5851194 | J23: =G23*0.86 -> 1.5146696 | L23: =E23*D23 -> 29.060522 | M23: =$D23*G23 -> 52.837313 | N23: =$D23*H23 -> 50.988007 | O23: =$D23*I23 -> 47.553581 | P23: =$D23*J23 -> 45.440089
A24: 2025 | B24: =VLOOKUP(A24,'[3]PRODUTOS ATIVOS'!$A$1:$AE$1048576,2,0) -> 9664 | C24: AZEITONA VERDE SEM CAROÇO SACHET 80 GR | D24: 30 | E24: =VLOOKUP(B24,CMV!A:L,12,0) -> 1.4094841 | F24: 0.45 | G24: =E24/(1-F24) -> 2.5626983 | H24: =G24*0.965 -> 2.4730039 | I24: =G24*0.9 -> 2.3064285 | J24: =G24*0.86 -> 2.2039205 | L24: =E24*D24 -> 42.284522 | M24: =$D24*G24 -> 76.880949 | N24: =$D24*H24 -> 74.190116 | O24: =$D24*I24 -> 69.192854 | P24: =$D24*J24 -> 66.117616
A25: 2026 | B25: =VLOOKUP(A25,'[3]PRODUTOS ATIVOS'!$A$1:$AE$1048576,2,0) -> 9665 | C25: AZEITONA VERDE FATIADA SACHET 80 GR | D25: 30 | E25: =VLOOKUP(B25,CMV!A:L,12,0) -> 1.4094841 | F25: 0.45 | G25: =E25/(1-F25) -> 2.5626983 | H25: =G25*0.965 -> 2.4730039 | I25: =G25*0.9 -> 2.3064285 | J25: =G25*0.86 -> 2.2039205 | L25: =E25*D25 -> 42.284522 | M25: =$D25*G25 -> 76.880949 | N25: =$D25*H25 -> 74.190116 | O25: =$D25*I25 -> 69.192854 | P25: =$D25*J25 -> 66.117616
A26: 2007 | B26: =VLOOKUP(A26,'[3]PRODUTOS ATIVOS'!$A$1:$AE$1048576,2,0) -> 9360 | C26: AZEITONA VERDE SEM CAROÇO SACHET 120 GR | D26: 18 | E26: =VLOOKUP(B26,CMV!A:L,12,0) -> 2.0309778 | F26: 0.45 | G26: =E26/(1-F26) -> 3.6926869 | H26: =G26*0.965 -> 3.5634428 | I26: =G26*0.9 -> 3.3234182 | J26: =G26*0.86 -> 3.1757107 | L26: =E26*D26 -> 36.5576 | M26: =$D26*G26 -> 66.468364 | N26: =$D26*H26 -> 64.141971 | O26: =$D26*I26 -> 59.821527 | P26: =$D26*J26 -> 57.162793
A27: 2008 | B27: =VLOOKUP(A27,'[3]PRODUTOS ATIVOS'!$A$1:$AE$1048576,2,0) -> 9361 | C27: AZEITONA VERDE FATIADA SACHET 120 GR | D27: 18 | E27: =VLOOKUP(B27,CMV!A:L,12,0) -> 2.0309778 | F27: 0.45 | G27: =E27/(1-F27) -> 3.6926869 | H27: =G27*0.965 -> 3.5634428 | I27: =G27*0.9 -> 3.3234182 | J27: =G27*0.86 -> 3.1757107 | L27: =E27*D27 -> 36.5576 | M27: =$D27*G27 -> 66.468364 | N27: =$D27*H27 -> 64.141971 | O27: =$D27*I27 -> 59.821527 | P27: =$D27*J27 -> 57.162793
A28: 2010 | B28: =VLOOKUP(A28,'[3]PRODUTOS ATIVOS'!$A$1:$AE$1048576,2,0) -> 9630 | C28: AZEITONA VERDE COM CAROÇO SACHET 150 GR | D28: 18 | E28: =VLOOKUP(B28,CMV!A:L,12,0) -> 2.108301 | F28: 0.45 | G28: =E28/(1-F28) -> 3.8332745 | H28: =G28*0.965 -> 3.6991099 | I28: =G28*0.9 -> 3.4499471 | J28: =G28*0.86 -> 3.2966161 | L28: =E28*D28 -> 37.949418 | M28: =$D28*G28 -> 68.998941 | N28: =$D28*H28 -> 66.583978 | O28: =$D28*I28 -> 62.099047 | P28: =$D28*J28 -> 59.339089
A30: 2011 | B30: =VLOOKUP(A30,'[3]PRODUTOS ATIVOS'!$A$1:$AE$1048576,2,0) -> 9565 | C30: AZEITONA VERDE COM CAROÇO SACHET 50 GR | D30: 36 | E30: =VLOOKUP(B30,CMV!A:L,12,0) -> 0.75241209 | F30: 0.45 | G30: =E30/(1-F30) -> 1.368022 | H30: =G30*0.965 -> 1.3201412 | I30: =G30*0.9 -> 1.2312198 | J30: =G30*0.86 -> 1.1764989 | L30: =E30*D30 -> 27.086835 | M30: =$D30*G30 -> 49.248791 | N30: =$D30*H30 -> 47.525084 | O30: =$D30*I30 -> 44.323912 | P30: =$D30*J30 -> 42.35396
A32: 3001 | B32: =VLOOKUP(A32,'[3]PRODUTOS ATIVOS'!$A$1:$AE$1048576,2,0) -> 9673 | C32: CHAMPIGNON INTEIRO SACHET 100 GR | D32: 30 | E32: =VLOOKUP(B32,CMV!A:L,12,0) -> 2.4540868 | F32: 0.45 | G32: =E32/(1-F32) -> 4.461976 | H32: =G32*0.965 -> 4.3058069 | I32: =G32*0.9 -> 4.0157784 | J32: =G32*0.86 -> 3.8372994 | L32: =E32*D32 -> 73.622604 | M32: =$D32*G32 -> 133.85928 | N32: =$D32*H32 -> 129.17421 | O32: =$D32*I32 -> 120.47335 | P32: =$D32*J32 -> 115.11898
A33: 3002 | B33: 10057 | C33: CHAMPIGNON FATIADO SACHET 100 GR | D33: 30 | E33: =VLOOKUP(B33,CMV!A:L,12,0) -> 2.2480868 | F33: 0.45 | G33: =E33/(1-F33) -> 4.0874306 | H33: =G33*0.965 -> 3.9443705 | I33: =G33*0.9 -> 3.6786875 | J33: =G33*0.86 -> 3.5151903 | L33: =E33*D33 -> 67.442605 | M33: =$D33*G33 -> 122.62292 | N33: =$D33*H33 -> 118.33112 | O33: =$D33*I33 -> 110.36063 | P33: =$D33*J33 -> 105.45571
A35: 6001 | B35: =VLOOKUP(A35,'[3]PRODUTOS ATIVOS'!$A$1:$AE$1048576,2,0) -> 9674 | C35: AZEITONA VERDE FATIADA SACHET 1,010 KG | D35: 6 | E35: =VLOOKUP(B35,CMV!A:L,12,0) -> 13.158033 | F35: 0.45 | G35: =E35/(1-F35) -> 23.923697 | H35: =G35*0.965 -> 23.086368 | I35: =G35*0.9 -> 21.531327 | J35: =G35*0.86 -> 20.574379 | L35: =E35*D35 -> 78.9482 | M35: =$D35*G35 -> 143.54218 | N35: =$D35*H35 -> 138.51821 | O35: =$D35*I35 -> 129.18796 | P35: =$D35*J35 -> 123.44628
A36: 6002 | B36: =VLOOKUP(A36,'[3]PRODUTOS ATIVOS'!$A$1:$AE$1048576,2,0) -> 9675 | C36: AZEITONA VERDE S/ CAROÇO SACHET 1,010 KG | D36: 6 | E36: =VLOOKUP(B36,CMV!A:L,12,0) -> 13.158033 | F36: 0.45 | G36: =E36/(1-F36) -> 23.923697 | H36: =G36*0.965 -> 23.086368 | I36: =G36*0.9 -> 21.531327 | J36: =G36*0.86 -> 20.574379 | L36: =E36*D36 -> 78.9482 | M36: =$D36*G36 -> 143.54218 | N36: =$D36*H36 -> 138.51821 | O36: =$D36*I36 -> 129.18796 | P36: =$D36*J36 -> 123.44628
A37: 6005 | B37: =VLOOKUP(A37,'[3]PRODUTOS ATIVOS'!$A$1:$AE$1048576,2,0) -> 9677 | C37: AZEITONA VERDE GRAUDA SACHET 1,010 KG | D37: 6 | E37: =VLOOKUP(B37,CMV!A:L,12,0) -> 13.471133 | F37: 0.45 | G37: =E37/(1-F37) -> 24.49297 | H37: =G37*0.965 -> 23.635716 | I37: =G37*0.9 -> 22.043673 | J37: =G37*0.86 -> 21.063954 | L37: =E37*D37 -> 80.8268 | M37: =$D37*G37 -> 146.95782 | N37: =$D37*H37 -> 141.81429 | O37: =$D37*I37 -> 132.26204 | P37: =$D37*J37 -> 126.38372
A38: 6006 | B38: =VLOOKUP(A38,'[3]PRODUTOS ATIVOS'!$A$1:$AE$1048576,2,0) -> 9678 | C38: AZEITONA VERDE MEDIA SACHET 1,010 KG | D38: 6 | E38: =VLOOKUP(B38,CMV!A:L,12,0) -> 11.602633 | F38: 0.45 | G38: =E38/(1-F38) -> 21.095697 | H38: =G38*0.965 -> 20.357348 | I38: =G38*0.9 -> 18.986127 | J38: =G38*0.86 -> 18.142299 | L38: =E38*D38 -> 69.6158 | M38: =$D38*G38 -> 126.57418 | N38: =$D38*H38 -> 122.14409 | O38: =$D38*I38 -> 113.91676 | P38: =$D38*J38 -> 108.8538
A39: 6007 | B39: =VLOOKUP(A39,'[3]PRODUTOS ATIVOS'!$A$1:$AE$1048576,2,0) -> 9679 | C39: AZEITONA VERDE MIUDA SACHET 1,010 KG | D39: 6 | E39: =VLOOKUP(B39,CMV!A:L,12,0) -> 7.5929333 | F39: 0.45 | G39: =E39/(1-F39) -> 13.805333 | H39: =G39*0.965 -> 13.322147 | I39: =G39*0.9 -> 12.4248 | J39: =G39*0.86 -> 11.872587 | L39: =E39*D39 -> 45.5576 | M39: =$D39*G39 -> 82.832 | N39: =$D39*H39 -> 79.93288 | O39: =$D39*I39 -> 74.5488 | P39: =$D39*J39 -> 71.23552
A40: 6014 | B40: =VLOOKUP(A40,'[3]PRODUTOS ATIVOS'!$A$1:$AE$1048576,2,0) -> 9680 | C40: CHAMPIGNON INTEIRO SACHET 1,010 KG | D40: 6 | E40: =VLOOKUP(B40,CMV!A:L,12,0) -> 21.544789 | F40: 0.45 | G40: =E40/(1-F40) -> 39.172343 | H40: =G40*0.965 -> 37.801311 | I40: =G40*0.9 -> 35.255109 | J40: =G40*0.86 -> 33.688215 | L40: =E40*D40 -> 129.26873 | M40: =$D40*G40 -> 235.03406 | N40: =$D40*H40 -> 226.80787 | O40: =$D40*I40 -> 211.53065 | P40: =$D40*J40 -> 202.12929
A41: 6015 | B41: =VLOOKUP(A41,'[3]PRODUTOS ATIVOS'!$A$1:$AE$1048576,2,0) -> 9681 | C41: CHAMPIGNON FATIADO SACHET 1,010 KG | D41: 6 | E41: =VLOOKUP(B41,CMV!A:L,12,0) -> 19.464189 | F41: 0.45 | G41: =E41/(1-F41) -> 35.389434 | H41: =G41*0.965 -> 34.150804 | I41: =G41*0.9 -> 31.850491 | J41: =G41*0.86 -> 30.434914 | L41: =E41*D41 -> 116.78513 | M41: =$D41*G41 -> 212.33661 | N41: =$D41*H41 -> 204.90482 | O41: =$D41*I41 -> 191.10295 | P41: =$D41*J41 -> 182.60948
A43: 5001 | B43: =VLOOKUP(A43,'[3]PRODUTOS ATIVOS'!$A$1:$AE$1048576,2,0) -> 9682 | C43: AZEITONA VERDE FATIADA BALDE 2 KG | D43: 2 | E43: =VLOOKUP(B43,CMV!A:L,12,0) -> 29.36581 | F43: 0.45 | G43: =E43/(1-F43) -> 53.392382 | H43: =G43*0.965 -> 51.523648 | I43: =G43*0.9 -> 48.053144 | J43: =G43*0.86 -> 45.917448 | L43: =E43*$D43 -> 58.73162 | M43: =$D43*G43 -> 106.78476 | N43: =$D43*H43 -> 103.0473 | O43: =$D43*I43 -> 96.106287 | P43: =$D43*J43 -> 91.834897
A44: 5002 | B44: =VLOOKUP(A44,'[3]PRODUTOS ATIVOS'!$A$1:$AE$1048576,2,0) -> 9685 | C44: AZEITONA VERDE S/ CAROÇO BALDE 2 KG | D44: 2 | E44: =VLOOKUP(B44,CMV!A:L,12,0) -> 29.36581 | F44: 0.45 | G44: =E44/(1-F44) -> 53.392382 | H44: =G44*0.965 -> 51.523648 | I44: =G44*0.9 -> 48.053144 | J44: =G44*0.86 -> 45.917448 | L44: =E44*$D44 -> 58.73162 | M44: =$D44*G44 -> 106.78476 | N44: =$D44*H44 -> 103.0473 | O44: =$D44*I44 -> 96.106287 | P44: =$D44*J44 -> 91.834897
A45: 5004 | B45: =VLOOKUP(A45,'[3]PRODUTOS ATIVOS'!$A$1:$AE$1048576,2,0) -> 9688 | C45: AZEITONA PRETA BALDE 2 KG | D45: 2 | E45: =VLOOKUP(B45,CMV!A:L,12,0) -> 31.8956 | F45: 0.45 | G45: =E45/(1-F45) -> 57.992 | H45: =G45*0.965 -> 55.96228 | I45: =G45*0.9 -> 52.1928 | J45: =G45*0.86 -> 49.87312 | L45: =E45*$D45 -> 63.7912 | M45: =$D45*G45 -> 115.984 | N45: =$D45*H45 -> 111.92456 | O45: =$D45*I45 -> 104.3856 | P45: =$D45*J45 -> 99.74624
A46: 5005 | B46: 9733 | C46: AZEITONA VERDE GRAUDA BALDE 2 KG | D46: 2 | E46: =VLOOKUP(B46,CMV!A:L,12,0) -> 29.98581 | F46: 0.45 | G46: =E46/(1-F46) -> 54.519655 | H46: =G46*0.965 -> 52.611467 | I46: =G46*0.9 -> 49.067689 | J46: =G46*0.86 -> 46.886903 | L46: =E46*$D46 -> 59.97162 | M46: =$D46*G46 -> 109.03931 | N46: =$D46*H46 -> 105.22293 | O46: =$D46*I46 -> 98.135378 | P46: =$D46*J46 -> 93.773806
A47: 5006 | B47: =VLOOKUP(A47,'[3]PRODUTOS ATIVOS'!$A$1:$AE$1048576,2,0) -> 9690 | C47: AZEITONA VERDE MEDIA BALDE 2 KG | D47: 2 | E47: =VLOOKUP(B47,CMV!A:L,12,0) -> 26.28581 | F47: 0.45 | G47: =E47/(1-F47) -> 47.792382 | H47: =G47*0.965 -> 46.119648 | I47: =G47*0.9 -> 43.013144 | J47: =G47*0.86 -> 41.101448 | L47: =E47*$D47 -> 52.57162 | M47: =$D47*G47 -> 95.584764 | N47: =$D47*H47 -> 92.239297 | O47: =$D47*I47 -> 86.026287 | P47: =$D47*J47 -> 82.202897
A48: 5007 | B48: =VLOOKUP(A48,'[3]PRODUTOS ATIVOS'!$A$1:$AE$1048576,2,0) -> 9564 | C48: AZEITONA VERDE MIUDA BALDE 2 KG | D48: 2 | E48: =VLOOKUP(B48,CMV!A:L,12,0) -> 18.34581 | F48: 0.45 | G48: =E48/(1-F48) -> 33.356018 | H48: =G48*0.965 -> 32.188558 | I48: =G48*0.9 -> 30.020416 | J48: =G48*0.86 -> 28.686176 | L48: =E48*$D48 -> 36.69162 | M48: =$D48*G48 -> 66.712036 | N48: =$D48*H48 -> 64.377115 | O48: =$D48*I48 -> 60.040833 | P48: =$D48*J48 -> 57.372351
A49: 5007 | B49: 9683 | C49: AZ PRETA FATIADA BALDE 2 KG | D49: 2 | E49: =VLOOKUP(B49,CMV!A:L,12,0) -> 40.2956 | F49: 0.45 | G49: =E49/(1-F49) -> 73.264727 | H49: =G49*0.965 -> 70.700462 | I49: =G49*0.9 -> 65.938255 | J49: =G49*0.86 -> 63.007665 | L49: =E49*$D49 -> 80.5912 | M49: =$D49*G49 -> 146.52945 | N49: =$D49*H49 -> 141.40092 | O49: =$D49*I49 -> 131.87651 | P49: =$D49*J49 -> 126.01533
A50: 5007 | B50: 9686 | C50: AZ PRETA SEM CAROÇO BALDE 2 KG | D50: 2 | E50: =VLOOKUP(B50,CMV!A:L,12,0) -> 40.2956 | F50: 0.45 | G50: =E50/(1-F50) -> 73.264727 | H50: =G50*0.965 -> 70.700462 | I50: =G50*0.9 -> 65.938255 | J50: =G50*0.86 -> 63.007665 | L50: =E50*$D50 -> 80.5912 | M50: =$D50*G50 -> 146.52945 | N50: =$D50*H50 -> 141.40092 | O50: =$D50*I50 -> 131.87651 | P50: =$D50*J50 -> 126.01533
...

Sheet TAB VAREJO
A1: TABELA GRAN ROMANO - VAREJO ** TABELA VÁLIDA PARA OS ESTADOS: SP - ES - MG - RJ ATUALIZADA 23/06/2025
A2: COD SANKHYA | B2: PRODUTO | C2: EMBALAGEM GRAMAS | D2: UNIDADES EM CAIXA | E2: PREÇO DE VENDA 28D UNIDADE | F2: PRECO VENDA 28D CX | G2: CÓD. EAN | H2: CÓD. DUN | I2: NCM | J2: QUANT. NO PALETE | K2: PRECO VENDA 7D CX | L2: PRECO VENDA 14D CX | M2: PRECO VENDA 21D CX | N2: PRECO VENDA 35D CX | O2: 0.0025
A4: 9645 | B4: AZ VERDE FATIADA | C4: 160 GR | D4: 12 | E4: =VLOOKUP(A4,'TABELA MÃE'!B:G,6,0) -> 6.868678 | F4: =E4*D4 -> 82.424136 | G4: 7898647930032 | H4: 17898647930039 | I4: 2005.70.00 | J4: 154 CXS | K4: =L4*0.995 -> 81.193945 | L4: =M4*0.995 -> 81.601955 | M4: =F4*0.995 -> 82.012015 | N4: =F4/0.995 -> 82.838328 | O4: =F4*0.25% -> 0.20606034
A5: 9646 | B5: AZ VERDE S/ CAROÇO | C5: 160 GR | D5: 12 | E5: =VLOOKUP(A5,'TABELA MÃE'!B:G,6,0) -> 6.868678 | F5: =E5*D5 -> 82.424136 | G5: 7898647930049 | H5: 17898647930046 | I5: 2005.70.00 | J5: 154 CXS | K5: =L5*0.995 -> 81.193945 | L5: =M5*0.995 -> 81.601955 | M5: =F5*0.995 -> 82.012015 | N5: =F5/0.995 -> 82.838328 | O5: =F5*0.25% -> 0.20606034
A6: 9648 | B6: AZ VERDE C/ CAROÇO | C6: 200 GR | D6: 12 | E6: =VLOOKUP(A6,'TABELA MÃE'!B:G,6,0) -> 7.1464545 | F6: =E6*D6 -> 85.757455 | G6: 7898647930063 | H6: 17898647930060 | I6: 2005.70.00 | J6: 154 CXS | K6: =L6*0.995 -> 84.477514 | L6: =M6*0.995 -> 84.902024 | M6: =F6*0.995 -> 85.328667 | N6: =F6/0.995 -> 86.188397 | O6: =F6*0.25% -> 0.21439364
A7: 9655 | B7: AZ PRETA C/CAROÇO GOURM | C7: 200 GR | D7: 12 | E7: =VLOOKUP(A7,'TABELA MÃE'!B:G,6,0) -> 8.2736109 | F7: =E7*D7 -> 99.283331 | G7: 7898647930711 | H7: 17898647930718 | I7: 2005.70.00 | J7: 154 CXS | K7: =L7*0.995 -> 97.801515 | L7: =M7*0.995 -> 98.29298 | M7: =F7*0.995 -> 98.786914 | N7: =F7/0.995 -> 99.782242 | O7: =F7*0.25% -> 0.24820833
A8: 9653 | B8: AZEITONA VERDE C/CAROÇO GOURMET | C8: 200 GR | D8: 12 | E8: =VLOOKUP(A8,'TABELA MÃE'!B:G,6,0) -> 7.8191818 | F8: =E8*D8 -> 93.830182 | G8: 7898647930865 | H8: 17898647930862 | I8: 2005.70.00 | J8: 154 CXS | K8: =L8*0.995 -> 92.429755 | L8: =M8*0.995 -> 92.894226 | M8: =F8*0.995 -> 93.361031 | N8: =F8/0.995 -> 94.30169
A9: 9654 | B9: AZEITONA VERDE S/CAROÇO GOURMET | C9: 160 GR | D9: 12 | E9: =VLOOKUP(A9,'TABELA MÃE'!B:G,6,0) -> 7.2294053 | F9: =E9*D9 -> 86.752863 | G9: 7898647930872 | H9: 17898647930879 | I9: 2005.70.00 | J9: 154 CXS | K9: =L9*0.995 -> 85.458066 | L9: =M9*0.995 -> 85.887503 | M9: =F9*0.995 -> 86.319099 | N9: =F9/0.995 -> 87.188807
A10: 9651 | B10: CHAMPIGNON INTEIRO | C10: 200 GR | D10: 12 | E10: =VLOOKUP(A10,'TABELA MÃE'!B:G,6,0) -> 10.666738 | F10: =E10*D10 -> 128.00086 | G10: 7898966673153 | H10: 17898966673150 | I10: 2003.10.00 | J10: 154 CXS | K10: =L10*0.995 -> 126.09043 | L10: =M10*0.995 -> 126.72405 | M10: =F10*0.995 -> 127.36085 | N10: =F10/0.995 -> 128.64408 | O10: =F10*0.25% -> 0.32000215
A11: 9652 | B11: CHAMPIGNON FATIADO | C11: 200 GR | D11: 12 | E11: =VLOOKUP(A11,'TABELA MÃE'!B:G,6,0) -> 9.9176473 | F11: =E11*D11 -> 119.01177 | G11: 7898966673160 | H11: 17898966673167 | I11: 2003.10.00 | J11: 154 CXS | K11: =L11*0.995 -> 117.2355 | L11: =M11*0.995 -> 117.82463 | M11: =F11*0.995 -> 118.41671 | N11: =F11/0.995 -> 119.60982 | O11: =F11*0.25% -> 0.29752942
A12: 9357 | B12: AZ VERDE C/ CAROÇO | C12: 500 GR | D12: 12 | E12: =VLOOKUP(A12,'TABELA MÃE'!B:G,6,0) -> 13.920897 | F12: =E12*D12 -> 167.05076 | G12: 7898647930070 | H12: 17898647930077 | I12: 2005.70.00 | J12: 70 CXS | K12: =L12*0.995 -> 164.55751 | L12: =M12*0.995 -> 165.38443 | M12: =F12*0.995 -> 166.21551 | N12: =F12/0.995 -> 167.89021 | O12: =F12*0.25% -> 0.41762691
A13: 9358 | B13: AZEITONA VERDE C/CAROÇO GOURMET | C13: 450 GR | D13: 12 | E13: =VLOOKUP(A13,'TABELA MÃE'!B:G,6,0) -> 14.537261 | F13: =E13*D13 -> 174.44713 | G13: 7898966673009 | H13: 17898966673013 | I13: 2005.70.00 | J13: 70 CXS | K13: =L13*0.995 -> 171.84348 | L13: =M13*0.995 -> 172.70702 | M13: =F13*0.995 -> 173.57489 | N13: =F13/0.995 -> 175.32375 | O13: =F13*0.25% -> 0.43611782
A14: 9359 | B14: AZEITONA VERDE S/CAROÇO GOURMET | C14: 400 GR | D14: 12 | E14: =VLOOKUP(A14,'TABELA MÃE'!B:G,6,0) -> 17.529988 | F14: =E14*D14 -> 210.35985 | G14: 7898966673023 | H14: 17898966673020 | I14: 2005.70.00 | J14: 70 CXS | K14: =L14*0.995 -> 207.22021 | L14: =M14*0.995 -> 208.26151 | M14: =F14*0.995 -> 209.30806 | N14: =F14/0.995 -> 211.41694 | O14: =F14*0.25% -> 0.52589964
A15: 9656 | B15: AZ PRETA C/CAROÇO GOURMET | C15: 400 GR | D15: 12 | E15: =VLOOKUP(A15,'TABELA MÃE'!B:G,6,0) -> 14.593901 | F15: =E15*D15 -> 175.12681 | G15: 7898647930001 | H15: 17898647930008 | I15: 2005.70.00 | J15: 70 CXS | K15: =L15*0.995 -> 172.51302 | L15: =M15*0.995 -> 173.37992 | M15: =F15*0.995 -> 174.25117 | N15: =F15/0.995 -> 176.00684 | O15: =F15*0.25% -> 0.43781702
O16: =F16*0.25% -> 0
A17: 9663 | B17: AZ VERDE C/ CAROÇO | C17: 80 GR | D17: 30 | E17: =VLOOKUP(A17,'TABELA MÃE'!B:G,6,0) -> 1.7612438 | F17: =E17*D17 -> 52.837313 | G17: 7898647930087 | H17: 17898647930084 | I17: 2005.70.00 | J17: 112 CXS | K17: =L17*0.995 -> 52.048709 | L17: =M17*0.995 -> 52.310261 | M17: =F17*0.995 -> 52.573126 | N17: =F17/0.995 -> 53.102827 | O17: =F17*0.25% -> 0.13209328
A18: 9664 | B18: AZ VERDE S/ CAROÇO | C18: 80 GR | D18: 30 | E18: =VLOOKUP(A18,'TABELA MÃE'!B:G,6,0) -> 2.5626983 | F18: =E18*D18 -> 76.880949 | G18: 7898647930834 | H18: 17898647930831 | I18: 2005.70.00 | J18: 112 CXS | K18: =L18*0.995 -> 75.733491 | L18: =M18*0.995 -> 76.114062 | M18: =F18*0.995 -> 76.496544 | N18: =F18/0.995 -> 77.267286 | O18: =F18*0.25% -> 0.19220237
A19: 9665 | B19: AZ VERDE FATIADA | C19: 80 GR | D19: 30 | E19: =VLOOKUP(A19,'TABELA MÃE'!B:G,6,0) -> 2.5626983 | F19: =E19*D19 -> 76.880949 | G19: 7898647930841 | H19: 17898647930848 | I19: 2005.70.00 | J19: 112 CXS | K19: =L19*0.995 -> 75.733491 | L19: =M19*0.995 -> 76.114062 | M19: =F19*0.995 -> 76.496544 | N19: =F19/0.995 -> 77.267286 | O19: =F19*0.25% -> 0.19220237
A20: 9360 | B20: AZ VERDE S/ CAROÇO | C20: 120 GR | D20: 18 | E20: =VLOOKUP(A20,'TABELA MÃE'!B:G,6,0) -> 3.6926869 | F20: =E20*D20 -> 66.468364 | G20: 7898647930094 | H20: 17898647930091 | I20: 2005.70.00 | J20: 112 CXS | K20: =L20*0.995 -> 65.476315 | L20: =M20*0.995 -> 65.805342 | M20: =F20*0.995 -> 66.136022 | N20: =F20/0.995 -> 66.802376 | O20: =F20*0.25% -> 0.16617091
A21: 9361 | B21: AZ VERDE FATIADA | C21: 120 GR | D21: 18 | E21: =VLOOKUP(A21,'TABELA MÃE'!B:G,6,0) -> 3.6926869 | F21: =E21*D21 -> 66.468364 | G21: 7898647930100 | H21: 17898647930107 | I21: 2005.70.00 | J21: 112 CXS | K21: =L21*0.995 -> 65.476315 | L21: =M21*0.995 -> 65.805342 | M21: =F21*0.995 -> 66.136022 | N21: =F21/0.995 -> 66.802376 | O21: =F21*0.25% -> 0.16617091
A22: 9630 | B22: AZ VERDE C/ CAROÇO | C22: 150 GR | D22: 18 | E22: =VLOOKUP(A22,'TABELA MÃE'!B:G,6,0) -> 3.8332745 | F22: =E22*D22 -> 68.998941 | G22: 7898647930124 | H22: 17898647930121 | I22: 2005.70.00 | J22: 112 CXS | K22: =L22*0.995 -> 67.969123 | L22: =M22*0.995 -> 68.310677 | M22: =F22*0.995 -> 68.653946 | N22: =F22/0.995 -> 69.345669 | O22: =F22*0.25% -> 0.17249735
O23: =F23*0.25% -> 0
A24: 9673 | B24: CHAMPIGNON INTEIRO | C24: 100 GR | D24: 30 | E24: =VLOOKUP(A24,'TABELA MÃE'!B:G,6,0) -> 4.461976 | F24: =E24*D24 -> 133.85928 | G24: 7898647930131 | H24: 17898647930138 | I24: 2003.10.00 | J24: 112 CXS | K24: =L24*0.995 -> 131.86141 | L24: =M24*0.995 -> 132.52403 | M24: =F24*0.995 -> 133.18998 | N24: =F24/0.995 -> 134.53194 | O24: =F24*0.25% -> 0.3346482
